<?xml version="1.0" ?>
<sdf version="1.6">
  <world name="world">
    <model name="neuromechfly_noLimits">
      <pose>0.0 0.0 0.0 0.0 -0.0 0.0</pose>
      <link name="A1A2">
        <pose>-0.3096565902233124 -6.095955882301496e-07 0.9105792045593262 0.0 -0.0 0.0</pose>
        <inertial>
          <pose>-0.2144250124692917 -6.603514339076355e-05 0.07071342319250107 -1.571784496307373 -2.825172185897827 -0.0002660344762261957</pose>
          <mass>8.571491383277525e-05</mass>
          <inertia>
            <ixx>5.510522483566601e-06</ixx>
            <ixy>0.0</ixy>
            <ixz>0.0</ixz>
            <iyy>4.152239737301167e-06</iyy>
            <iyz>0.0</iyz>
            <izz>2.884050584870507e-06</izz>
          </inertia>
        </inertial>
        <visual name="A1A2_visual">
          <pose>-2.3841858265427618e-08 -9.094947153254554e-14 -9.536743306171047e-08 0.0 -0.0 0.0</pose>
          <geometry>
            <mesh>
              <uri>../meshes/stl/A1A2.stl</uri>
              <scale>1000.0 1000.0 1000.0</scale>
            </mesh>
          </geometry>
          <material/>
        </visual>
      </link>
      <link name="A3">
        <pose>-0.6661300659179688 -6.225838546924933e-07 0.9098724126815796 0.0 -0.2617994546890259 0.0</pose>
        <inertial>
          <pose>-0.0598759651184082 -6.470004882430658e-05 -0.022680843248963356 -1.5709697008132935 -3.0543622970581055 -2.9146691304049455e-05</pose>
          <mass>0.00010704018580061077</mass>
          <inertia>
            <ixx>9.01550963523884e-06</ixx>
            <ixy>0.0</ixy>
            <ixz>0.0</ixz>
            <iyy>6.501265861095985e-06</iyy>
            <iyz>0.0</iyz>
            <izz>4.180772816288316e-06</izz>
          </inertia>
        </inertial>
        <visual name="A3_visual">
          <pose>9.536743306171047e-08 -9.094947153254554e-14 -1.1920928955078125e-07 0.0 7.324219097881723e-08 0.0</pose>
          <geometry>
            <mesh>
              <uri>../meshes/stl/A3.stl</uri>
              <scale>1000.0 1000.0 1000.0</scale>
            </mesh>
          </geometry>
          <material/>
        </visual>
      </link>
      <link name="A4">
        <pose>-0.8957122564315796 -6.236073204490822e-07 0.8487270474433899 0.0 -0.26179951429367065 0.0</pose>
        <inertial>
          <pose>-0.06720199435949326 -2.9355969672906213e-05 -0.01719794236123562 -1.570814609527588 -3.053770065307617 -5.08529701619409e-05</pose>
          <mass>9.752435108452857e-05</mass>
          <inertia>
            <ixx>8.065754648441029e-06</ixx>
            <ixy>0.0</ixy>
            <ixz>0.0</ixz>
            <iyy>6.227746413355443e-06</iyy>
            <iyz>0.0</iyz>
            <izz>3.2575275005153073e-06</izz>
          </inertia>
        </inertial>
        <visual name="A4_visual">
          <pose>9.536742595628311e-08 0.0 -1.1920928244535389e-07 0.0 4.882812376649781e-08 0.0</pose>
          <geometry>
            <mesh>
              <uri>../meshes/stl/A4.stl</uri>
              <scale>1000.0 1000.0 1000.0</scale>
            </mesh>
          </geometry>
          <material/>
        </visual>
      </link>
      <link name="A5">
        <pose>-1.1026822328567505 -6.257803306652931e-07 0.7931721210479736 0.0 -7.450580596923828e-08 0.0</pose>
        <inertial>
          <pose>-0.08348407596349716 2.2320235075312667e-05 -0.04062872752547264 1.571494698524475 3.1243011951446533 -0.00021047440532129258</pose>
          <mass>9.704450609731538e-05</mass>
          <inertia>
            <ixx>6.510440853944567e-06</ixx>
            <ixy>0.0</ixy>
            <ixz>0.0</ixz>
            <iyy>5.05814366550794e-06</iyy>
            <iyz>0.0</iyz>
            <izz>3.3950601886867857e-06</izz>
          </inertia>
        </inertial>
        <visual name="A5_visual">
          <pose>9.536743306171047e-08 0.0 1.775236455614504e-07 0.0 1.3554095801282529e-07 0.0</pose>
          <geometry>
            <mesh>
              <uri>../meshes/stl/A5.stl</uri>
              <scale>1000.0 1000.0 1000.0</scale>
            </mesh>
          </geometry>
          <material/>
        </visual>
      </link>
      <link name="A6">
        <pose>-1.3707311153411865 -6.225402557902271e-07 0.79367595911026 0.0 0.5235984921455383 0.0</pose>
        <inertial>
          <pose>-0.05385637283325195 1.0378301340097096e-05 -0.03479938581585884 1.5700455904006958 -3.048633098602295 0.00011918242671526968</pose>
          <mass>6.267604318477003e-05</mass>
          <inertia>
            <ixx>2.5733295717095013e-06</ixx>
            <ixy>0.0</ixy>
            <ixz>0.0</ixz>
            <iyy>2.034982036218061e-06</iyy>
            <iyz>0.0</iyz>
            <izz>1.9706170131644477e-06</izz>
          </inertia>
        </inertial>
        <visual name="A6_visual">
          <pose>9.536743306171047e-08 -4.547473576627277e-14 9.536743306171047e-08 0.0 -0.0 0.0</pose>
          <geometry>
            <mesh>
              <uri>../meshes/stl/A6.stl</uri>
              <scale>1000.0 1000.0 1000.0</scale>
            </mesh>
          </geometry>
          <material/>
        </visual>
      </link>
      <link name="Haustellum">
        <pose>0.498359739780426 0.00023461313685402274 0.9294242858886719 0.0 -1.221730351448059 0.0</pose>
        <inertial>
          <pose>0.20060519874095917 0.004706570412963629 -0.008783726952970028 -0.014603089541196823 -0.0014268209924921393 3.1233773231506348</pose>
          <mass>6.941066853014398e-06</mass>
          <inertia>
            <ixx>4.906921130721797e-08</ixx>
            <ixy>0.0</ixy>
            <ixz>0.0</ixz>
            <iyy>5.888609054504224e-08</iyy>
            <iyz>0.0</iyz>
            <izz>8.014616447234784e-08</izz>
          </inertia>
        </inertial>
        <visual name="Haustellum_visual">
          <pose>4.7683744952564666e-08 6.984919587171845e-11 4.7683744952564666e-08 0.0 2.4414063659605745e-08 0.0</pose>
          <geometry>
            <mesh>
              <uri>../meshes/stl/Haustellum.stl</uri>
              <scale>1000.0 1000.0 1000.0</scale>
            </mesh>
          </geometry>
          <material/>
        </visual>
      </link>
      <link name="Head">
        <pose>0.497922420501709 -6.537505896631046e-07 1.2107713222503662 0.0 0.174532949924469 0.0</pose>
        <inertial>
          <pose>0.2020912915468216 -0.004383999854326248 0.04394782334566116 1.4678964614868164 0.15526525676250458 0.057784806936979294</pose>
          <mass>8.113157308044636e-05</mass>
          <inertia>
            <ixx>3.9411131484113794e-06</ixx>
            <ixy>0.0</ixy>
            <ixz>0.0</ixz>
            <iyy>3.049440828134831e-06</iyy>
            <iyz>0.0</iyz>
            <izz>2.933679242779478e-06</izz>
          </inertia>
        </inertial>
        <visual name="Head_visual">
          <pose>0.0 -2.2737367544323206e-13 1.430511673561341e-07 0.0 2.4414060106892066e-08 0.0</pose>
          <geometry>
            <mesh>
              <uri>../meshes/stl/Head.stl</uri>
              <scale>1000.0 1000.0 1000.0</scale>
            </mesh>
          </geometry>
          <material/>
        </visual>
      </link>
      <link name="Head_roll">
        <pose>0.49792253971099854 -6.537503054460103e-07 1.2107712030410767 0.0 -0.0 0.0</pose>
        <inertial>
          <pose>-9.536743306171047e-08 -4.547473576627277e-14 -1.9073486612342094e-07 -0.0 -0.0 0.0</pose>
          <mass>0.0</mass>
          <inertia>
            <ixx>0.0</ixx>
            <ixy>0.0</ixy>
            <ixz>0.0</ixz>
            <iyy>0.0</iyy>
            <iyz>0.0</iyz>
            <izz>0.0</izz>
          </inertia>
        </inertial>
      </link>
      <link name="Head_yaw">
        <pose>0.49792245030403137 -6.53750419132848e-07 1.2107712030410767 0.0 -0.0 0.0</pose>
        <inertial>
          <pose>4.7683716530855236e-08 -1.364242106869501e-13 -1.9073486612342094e-07 -0.0 -0.0 0.0</pose>
          <mass>0.0</mass>
          <inertia>
            <ixx>0.0</ixx>
            <ixy>0.0</ixy>
            <ixz>0.0</ixz>
            <iyy>0.0</iyy>
            <iyz>0.0</iyz>
            <izz>0.0</izz>
          </inertia>
        </inertial>
      </link>
      <link name="LAntenna">
        <pose>0.9482775330543518 0.06690020859241486 1.273026704788208 0.5759587287902832 7.450578465295621e-08 -6.351129067105887e-10</pose>
        <inertial>
          <pose>0.050914015620946884 0.013138963840901852 -0.1115608960390091 1.5705822706222534 -1.4220702648162842 0.3274625539779663</pose>
          <mass>1.7777389383760332e-06</mass>
          <inertia>
            <ixx>4.800929362699907e-09</ixx>
            <ixy>0.0</ixy>
            <ixz>0.0</ixz>
            <iyy>1.2517838477520334e-08</iyy>
            <iyz>0.0</iyz>
            <izz>1.0265764000425106e-08</izz>
          </inertia>
        </inertial>
        <visual name="LAntenna_visual">
          <pose>0.0 1.430511673561341e-07 1.4901164746561335e-08 0.0 5.899165600453671e-09 5.8007505465695886e-09</pose>
          <geometry>
            <mesh>
              <uri>../meshes/stl/LAntenna.stl</uri>
              <scale>1000.0 1000.0 1000.0</scale>
            </mesh>
          </geometry>
          <material/>
        </visual>
      </link>
      <link name="LEye">
        <pose>0.7419561147689819 -5.63652520213509e-07 1.258327841758728 0.0 3.7252892326478104e-08 0.0</pose>
        <inertial>
          <pose>-0.007038166280835867 0.30096420645713806 -0.023739032447338104 0.1506286859512329 0.08522723615169525 -1.1666678190231323</pose>
          <mass>9.502325241495403e-06</mass>
          <inertia>
            <ixx>1.8882172747563606e-07</ixx>
            <ixy>0.0</ixy>
            <ixz>0.0</ixz>
            <iyy>1.2190588344546151e-07</iyy>
            <iyz>0.0</iyz>
            <izz>8.661282451410771e-08</izz>
          </inertia>
        </inertial>
        <visual name="LEye_visual">
          <pose>-4.768373074170995e-08 -9.094947153254554e-14 -6.772745564376237e-08 0.0 -6.73532207784433e-09 0.0</pose>
          <geometry>
            <mesh>
              <uri>../meshes/stl/LEye.stl</uri>
              <scale>1000.0 1000.0 1000.0</scale>
            </mesh>
          </geometry>
          <material/>
        </visual>
      </link>
      <link name="LFCoxa">
        <pose>0.41799992322921753 0.26999956369400024 1.0799976587295532 0.0 -0.0 1.1175868053214799e-07</pose>
        <inertial>
          <pose>0.002981091383844614 -0.03152109310030937 -0.25312453508377075 -0.045758262276649475 -0.04927655681967735 0.5402534008026123</pose>
          <mass>5.741707610995013e-06</mass>
          <inertia>
            <ixx>6.081016980815336e-08</ixx>
            <ixy>0.0</ixy>
            <ixz>0.0</ixz>
            <iyy>5.7202312502505616e-08</iyy>
            <iyz>0.0</iyz>
            <izz>1.4003987505627087e-08</izz>
          </inertia>
        </inertial>
        <visual name="LFCoxa_visual">
          <pose>9.53674614834199e-08 4.768373074170995e-08 -9.536743306171047e-08 0.0 -0.0 -4.947185328063597e-09</pose>
          <geometry>
            <mesh>
              <uri>../meshes/stl/LFCoxa.stl</uri>
              <scale>1000.0 1000.0 1000.0</scale>
            </mesh>
          </geometry>
          <material/>
        </visual>
      </link>
      <link name="LFCoxa_roll">
        <pose>0.41799983382225037 0.2699994742870331 1.0799976587295532 0.0 -0.0 0.174532949924469</pose>
        <inertial>
          <pose>9.536744727256519e-08 3.5762791839033525e-08 -9.536743306171047e-08 -0.0 -0.0 0.0</pose>
          <mass>0.0</mass>
          <inertia>
            <ixx>0.0</ixx>
            <ixy>0.0</ixy>
            <ixz>0.0</ixz>
            <iyy>0.0</iyy>
            <iyz>0.0</iyz>
            <izz>0.0</izz>
          </inertia>
        </inertial>
      </link>
      <link name="LFCoxa_yaw">
        <pose>0.41799986362457275 0.26999950408935547 1.0799976587295532 0.0 -0.0 3.7252892326478104e-08</pose>
        <inertial>
          <pose>9.53674614834199e-08 2.3841865370854975e-08 -9.536743306171047e-08 -0.0 -0.0 0.0</pose>
          <mass>0.0</mass>
          <inertia>
            <ixx>0.0</ixx>
            <ixy>0.0</ixy>
            <ixz>0.0</ixz>
            <iyy>0.0</iyy>
            <iyz>0.0</iyz>
            <izz>0.0</izz>
          </inertia>
        </inertial>
      </link>
      <link name="LFFemur">
        <pose>0.4179999828338623 0.26999956369400024 0.6545163989067078 0.0 -0.0 1.8626445807967684e-07</pose>
        <inertial>
          <pose>-0.019857650622725487 -0.006747391074895859 -0.35944435000419617 0.05809037387371063 1.6430429220199585 1.0958918333053589</pose>
          <mass>7.992114412322805e-06</mass>
          <inertia>
            <ixx>1.4379391088932434e-08</ixx>
            <ixy>0.0</ixy>
            <ixz>0.0</ixz>
            <iyy>2.726184447902739e-07</iyy>
            <iyz>0.0</iyz>
            <izz>2.747166063190922e-07</izz>
          </inertia>
        </inertial>
        <visual name="LFFemur_visual">
          <pose>1.4305119577784353e-07 7.152559788892177e-08 0.0 0.0 -0.0 1.2099741653059937e-08</pose>
          <geometry>
            <mesh>
              <uri>../meshes/stl/LFFemur.stl</uri>
              <scale>1000.0 1000.0 1000.0</scale>
            </mesh>
          </geometry>
          <material/>
        </visual>
      </link>
      <link name="LFFemur_roll">
        <pose>0.41800007224082947 0.269999623298645 0.6545163989067078 0.0 -0.0 -0.1745327115058899</pose>
        <inertial>
          <pose>7.152560499434912e-08 2.3841867147211815e-08 4.7683716530855236e-08 -0.0 -0.0 0.0</pose>
          <mass>0.0</mass>
          <inertia>
            <ixx>0.0</ixx>
            <ixy>0.0</ixy>
            <ixz>0.0</ixz>
            <iyy>0.0</iyy>
            <iyz>0.0</iyz>
            <izz>0.0</izz>
          </inertia>
        </inertial>
      </link>
      <link name="LFTarsus1">
        <pose>0.41800007224082947 0.269999623298645 -0.5691056847572327 1.6817360004584003e-10 -0.6806782484054565 -0.3490656018257141</pose>
        <inertial>
          <pose>-0.004590393044054508 -0.009428766556084156 -0.12341514974832535 -2.4325942993164062 -1.5347647666931152 -0.2797248959541321</pose>
          <mass>5.902334137063546e-07</mass>
          <inertia>
            <ixx>2.1051966699155085e-10</ixx>
            <ixy>0.0</ixy>
            <ixz>0.0</ixz>
            <iyy>2.659897361575242e-09</iyy>
            <iyz>0.0</iyz>
            <izz>2.6763323778620767e-09</izz>
          </inertia>
        </inertial>
        <collision name="LFTarsus1_collision">
          <pose>-7.152558367806705e-08 -2.3841865370854975e-08 -8.344650836988876e-08 -1.178349862129835e-08 -0.0 4.150188104290464e-08</pose>
          <geometry>
            <mesh>
              <uri>../meshes/stl/LFTarsus1.stl</uri>
              <scale>1000.0 1000.0 1000.0</scale>
            </mesh>
          </geometry>
        </collision>
        <visual name="LFTarsus1_visual">
          <pose>-7.152558367806705e-08 -2.3841865370854975e-08 -8.344650836988876e-08 -1.178349862129835e-08 -0.0 4.150188104290464e-08</pose>
          <geometry>
            <mesh>
              <uri>../meshes/stl/LFTarsus1.stl</uri>
              <scale>1000.0 1000.0 1000.0</scale>
            </mesh>
          </geometry>
          <material/>
        </visual>
      </link>
      <link name="LFTarsus2">
        <pose>0.5513635873794556 0.2214592844247818 -0.7443651556968689 5.6197116293787985e-08 -1.4901156930591242e-07 -0.5235984921455383</pose>
        <inertial>
          <pose>-0.0012888911878690124 -0.005322647746652365 -0.0891428142786026 0.7475929260253906 1.520503282546997 0.06141968071460724</pose>
          <mass>2.658976343874435e-07</mass>
          <inertia>
            <ixx>6.580080192111077e-11</ixx>
            <ixy>0.0</ixy>
            <ixz>0.0</ixz>
            <iyy>5.158320991685466e-10</iyy>
            <iyz>0.0</iyz>
            <izz>5.066423199905649e-10</izz>
          </inertia>
        </inertial>
        <collision name="LFTarsus2_collision">
          <pose>-1.6689305937234167e-07 4.7683723636282593e-08 2.5286317395512015e-07 -1.0553027784965252e-08 -6.461144153036003e-08 4.8828141530066205e-08</pose>
          <geometry>
            <mesh>
              <uri>../meshes/stl/LFTarsus2.stl</uri>
              <scale>1000.0 1000.0 1000.0</scale>
            </mesh>
          </geometry>
        </collision>
        <visual name="LFTarsus2_visual">
          <pose>-1.6689305937234167e-07 4.7683723636282593e-08 2.5286317395512015e-07 -1.0553027784965252e-08 -6.461144153036003e-08 4.8828141530066205e-08</pose>
          <geometry>
            <mesh>
              <uri>../meshes/stl/LFTarsus2.stl</uri>
              <scale>1000.0 1000.0 1000.0</scale>
            </mesh>
          </geometry>
          <material/>
        </visual>
      </link>
      <link name="LFTarsus3">
        <pose>0.5513637065887451 0.22145918011665344 -0.8980337381362915 -0.13970132172107697 0.6684359312057495 -0.7467113733291626</pose>
        <inertial>
          <pose>-0.0010801912285387516 -0.003454161575064063 -0.05935225635766983 1.23808753490448 1.4883232116699219 -0.43491846323013306</pose>
          <mass>1.5048445915428457e-07</mass>
          <inertia>
            <ixx>3.169918415337038e-11</ixx>
            <ixy>0.0</ixy>
            <ixz>0.0</ixz>
            <iyy>1.3182265888473536e-10</iyy>
            <iyz>0.0</iyz>
            <izz>1.280254388363746e-10</izz>
          </inertia>
        </inertial>
        <collision name="LFTarsus3_collision">
          <pose>-4.7683720083568915e-08 9.536745437799254e-08 7.152557657263969e-08 -3.662108483126758e-08 -9.765624753299562e-08 0.0</pose>
          <geometry>
            <mesh>
              <uri>../meshes/stl/LFTarsus3.stl</uri>
              <scale>1000.0 1000.0 1000.0</scale>
            </mesh>
          </geometry>
        </collision>
        <visual name="LFTarsus3_visual">
          <pose>-4.7683720083568915e-08 9.536745437799254e-08 7.152557657263969e-08 -3.662108483126758e-08 -9.765624753299562e-08 0.0</pose>
          <geometry>
            <mesh>
              <uri>../meshes/stl/LFTarsus3.stl</uri>
              <scale>1000.0 1000.0 1000.0</scale>
            </mesh>
          </geometry>
          <material/>
        </visual>
      </link>
      <link name="LFTarsus4">
        <pose>0.4976819157600403 0.252452552318573 -0.9745805263519287 -0.9117427468299866 1.2139229774475098 -1.5786769390106201</pose>
        <inertial>
          <pose>0.0008697923622094095 -0.0014729026006534696 -0.049972958862781525 2.727632522583008 1.4870375394821167 -0.40846455097198486</pose>
          <mass>1.1769954786975934e-07</mass>
          <inertia>
            <ixx>2.246691603437497e-11</ixx>
            <ixy>0.0</ixy>
            <ixz>0.0</ixz>
            <iyy>7.489486534017188e-11</iyy>
            <iyz>0.0</iyz>
            <izz>7.742831204708704e-11</izz>
          </inertia>
        </inertial>
        <collision name="LFTarsus4_collision">
          <pose>1.7881387037732566e-08 0.0 -4.7683723636282593e-08 1.2207032717981292e-08 -8.544927965203897e-08 2.4414083199530978e-08</pose>
          <geometry>
            <mesh>
              <uri>../meshes/stl/LFTarsus4.stl</uri>
              <scale>1000.0 1000.0 1000.0</scale>
            </mesh>
          </geometry>
        </collision>
        <visual name="LFTarsus4_visual">
          <pose>1.7881387037732566e-08 0.0 -4.7683723636282593e-08 1.2207032717981292e-08 -8.544927965203897e-08 2.4414083199530978e-08</pose>
          <geometry>
            <mesh>
              <uri>../meshes/stl/LFTarsus4.stl</uri>
              <scale>1000.0 1000.0 1000.0</scale>
            </mesh>
          </geometry>
          <material/>
        </visual>
      </link>
      <link name="LFTarsus5">
        <pose>0.42929863929748535 0.3029117286205292 -0.9931920170783997 0.7835025191307068 2.211385488510132 0.05975201725959778</pose>
        <inertial>
          <pose>0.0025774938985705376 -0.0008883955888450146 -0.05205831676721573 1.3573895692825317 -1.6784625053405762 -0.10700485855340958</pose>
          <mass>1.4544444513923852e-07</mass>
          <inertia>
            <ixx>3.336258707865785e-11</ixx>
            <ixy>0.0</ixy>
            <ixz>0.0</ixz>
            <iyy>1.1437002622355968e-10</iyy>
            <iyz>0.0</iyz>
            <izz>1.2046815773145696e-10</izz>
          </inertia>
        </inertial>
        <collision name="LFTarsus5_collision">
          <pose>-2.3841842278216063e-08 -9.53674614834199e-08 -1.4305115314527939e-07 -4.882812376649781e-08 -7.324224071680874e-08 2.4414086752244657e-08</pose>
          <geometry>
            <mesh>
              <uri>../meshes/stl/LFTarsus5.stl</uri>
              <scale>1000.0 1000.0 1000.0</scale>
            </mesh>
          </geometry>
        </collision>
        <visual name="LFTarsus5_visual">
          <pose>-2.3841842278216063e-08 -9.53674614834199e-08 -1.4305115314527939e-07 -4.882812376649781e-08 -7.324224071680874e-08 2.4414086752244657e-08</pose>
          <geometry>
            <mesh>
              <uri>../meshes/stl/LFTarsus5.stl</uri>
              <scale>1000.0 1000.0 1000.0</scale>
            </mesh>
          </geometry>
          <material/>
        </visual>
      </link>
      <link name="LFTibia">
        <pose>0.41800007224082947 0.269999623298645 -0.050723545253276825 0.0 -0.0 -0.1745326966047287</pose>
        <inertial>
          <pose>0.01139717549085617 -0.003587581217288971 -0.2930237948894501 0.11942432075738907 1.624285101890564 -2.2962024211883545</pose>
          <mass>2.6268343212263377e-06</mass>
          <inertia>
            <ixx>2.030217068615563e-09</ixx>
            <ixy>0.0</ixy>
            <ixz>0.0</ixz>
            <iyy>5.494782665026217e-08</iyy>
            <iyz>0.0</iyz>
            <izz>5.543577309004056e-08</izz>
          </inertia>
        </inertial>
        <visual name="LFTibia_visual">
          <pose>7.152560499434912e-08 2.3841867147211815e-08 5.9604645663569045e-09 0.0 -0.0 -2.4414063659605745e-08</pose>
          <geometry>
            <mesh>
              <uri>../meshes/stl/LFTibia.stl</uri>
              <scale>1000.0 1000.0 1000.0</scale>
            </mesh>
          </geometry>
          <material/>
        </visual>
      </link>
      <link name="LHaltere">
        <pose>-0.25896793603897095 0.21355582773685455 0.9370104670524597 0.0 -0.0 0.0</pose>
        <inertial>
          <pose>-0.00820546131581068 0.20605282485485077 -0.0006526947254315019 -1.5760596990585327 0.0750126987695694 -0.001004880527034402</pose>
          <mass>1.4160896935430824e-06</mass>
          <inertia>
            <ixx>1.4022433176462182e-08</ixx>
            <ixy>0.0</ixy>
            <ixz>0.0</ixz>
            <iyy>1.3647846009782277e-08</iyy>
            <iyz>0.0</iyz>
            <izz>1.9726870568252306e-09</izz>
          </inertia>
        </inertial>
        <visual name="LHaltere_visual">
          <pose>-4.7683716530855236e-08 4.7683716530855236e-08 0.0 0.0 -0.0 0.0</pose>
          <geometry>
            <mesh>
              <uri>../meshes/stl/LHaltere.stl</uri>
              <scale>1000.0 1000.0 1000.0</scale>
            </mesh>
          </geometry>
          <material/>
        </visual>
      </link>
      <link name="LHaltere_roll">
        <pose>-0.25896793603897095 0.2135557234287262 0.9370104670524597 0.0 -0.0 0.0</pose>
        <inertial>
          <pose>-4.7683716530855236e-08 4.7683716530855236e-08 0.0 -0.0 -0.0 0.0</pose>
          <mass>0.0</mass>
          <inertia>
            <ixx>0.0</ixx>
            <ixy>0.0</ixy>
            <ixz>0.0</ixz>
            <iyy>0.0</iyy>
            <iyz>0.0</iyz>
            <izz>0.0</izz>
          </inertia>
        </inertial>
      </link>
      <link name="LHaltere_yaw">
        <pose>-0.25896793603897095 0.21355576813220978 0.9370104670524597 0.0 -0.0 0.0</pose>
        <inertial>
          <pose>-4.7683716530855236e-08 4.7683716530855236e-08 0.0 -0.0 -0.0 0.0</pose>
          <mass>0.0</mass>
          <inertia>
            <ixx>0.0</ixx>
            <ixy>0.0</ixy>
            <ixz>0.0</ixz>
            <iyy>0.0</iyy>
            <iyz>0.0</iyz>
            <izz>0.0</izz>
          </inertia>
        </inertial>
      </link>
      <link name="LHCoxa">
        <pose>-0.14771784842014313 0.08699284493923187 0.607223391532898 0.0 0.10821041464805603 0.0</pose>
        <inertial>
          <pose>-0.0038198705296963453 0.020953847095370293 -0.10100871324539185 -0.1921554058790207 -1.2247354984283447 -1.7353723049163818</pose>
          <mass>3.2548936150106453e-06</mass>
          <inertia>
            <ixx>8.053343720086051e-09</ixx>
            <ixy>0.0</ixy>
            <ixz>0.0</ixz>
            <iyy>1.3522487380450855e-08</iyy>
            <iyz>0.0</iyz>
            <izz>1.5295869184823672e-08</izz>
          </inertia>
        </inertial>
        <visual name="LHCoxa_visual">
          <pose>-3.576278118089249e-08 -5.9604645663569045e-09 5.6624404720651e-08 0.0 1.2207031829802872e-08 0.0</pose>
          <geometry>
            <mesh>
              <uri>../meshes/stl/LHCoxa.stl</uri>
              <scale>1000.0 1000.0 1000.0</scale>
            </mesh>
          </geometry>
          <material/>
        </visual>
      </link>
      <link name="LHCoxa_roll">
        <pose>-0.1477176696062088 0.08699287474155426 0.6072235703468323 -0.06021381914615631 1.8626465703164286e-08 -2.3283082128955357e-09</pose>
        <inertial>
          <pose>2.3841840501859224e-08 3.5762791839033525e-08 -4.4330956683324985e-08 -0.0 -0.0 0.0</pose>
          <mass>0.0</mass>
          <inertia>
            <ixx>0.0</ixx>
            <ixy>0.0</ixy>
            <ixz>0.0</ixz>
            <iyy>0.0</iyy>
            <iyz>0.0</iyz>
            <izz>0.0</izz>
          </inertia>
        </inertial>
      </link>
      <link name="LHCoxa_yaw">
        <pose>-0.14771780371665955 0.08699284493923187 0.6072235107421875 -0.060213856399059296 -1.862645682138009e-08 1.1641535513362555e-09</pose>
        <inertial>
          <pose>8.344647994817933e-08 2.9802322387695312e-08 9.685755308908028e-09 -0.0 -0.0 0.0</pose>
          <mass>0.0</mass>
          <inertia>
            <ixx>0.0</ixx>
            <ixy>0.0</ixy>
            <ixz>0.0</ixz>
            <iyy>0.0</iyy>
            <iyz>0.0</iyz>
            <izz>0.0</izz>
          </inertia>
        </inertial>
      </link>
      <link name="LHFemur">
        <pose>-0.147992342710495 0.07476705312728882 0.40818148851394653 -0.06021381914615631 9.313236404295822e-08 -6.984927303221866e-09</pose>
        <inertial>
          <pose>0.03316854313015938 -0.018455805256962776 -0.43907609581947327 -0.0918315201997757 1.5981297492980957 -2.257822036743164</pose>
          <mass>1.1113719808091789e-05</mass>
          <inertia>
            <ixx>2.672367898235558e-08</ixx>
            <ixy>0.0</ixy>
            <ixz>0.0</ixz>
            <iyy>5.206395757677327e-07</iyy>
            <iyz>0.0</iyz>
            <izz>5.279111635696818e-07</izz>
          </inertia>
        </inertial>
        <visual name="LHFemur_visual">
          <pose>2.3841831620075027e-08 -2.980232949312267e-08 2.9057265038545665e-08 -1.831054241563379e-08 -9.325617611466441e-09 1.6583634465661135e-09</pose>
          <geometry>
            <mesh>
              <uri>../meshes/stl/LHFemur.stl</uri>
              <scale>1000.0 1000.0 1000.0</scale>
            </mesh>
          </geometry>
          <material/>
        </visual>
      </link>
      <link name="LHFemur_roll">
        <pose>-0.14799228310585022 0.07476704567670822 0.40818148851394653 -0.12112926691770554 -0.10742367804050446 0.013050301931798458</pose>
        <inertial>
          <pose>3.5762738548328343e-08 -3.576280249717456e-08 -2.9802318834981634e-08 -0.0 -0.0 0.0</pose>
          <mass>0.0</mass>
          <inertia>
            <ixx>0.0</ixx>
            <ixy>0.0</ixy>
            <ixz>0.0</ixz>
            <iyy>0.0</iyy>
            <iyz>0.0</iyz>
            <izz>0.0</izz>
          </inertia>
        </inertial>
      </link>
      <link name="LHTarsus1">
        <pose>0.016643226146697998 -0.1078481525182724 -1.0925801992416382 -0.32668283581733704 -0.9778951406478882 0.267324298620224</pose>
        <inertial>
          <pose>-0.002592901699244976 0.004060067236423492 -0.16763935983181 -1.211210012435913 1.5842972993850708 -0.6816871762275696</pose>
          <mass>1.3249969982172918e-06</mass>
          <inertia>
            <ixx>7.359383871538027e-10</ixx>
            <ixy>0.0</ixy>
            <ixz>0.0</ixz>
            <iyy>1.3962060439191365e-08</iyy>
            <iyz>0.0</iyz>
            <izz>1.3844624883879968e-08</izz>
          </inertia>
        </inertial>
        <collision name="LHTarsus1_collision">
          <pose>1.1920921139108032e-07 -2.3841867147211815e-08 -1.4007072479671479e-07 -1.831051221756752e-08 1.4648428248165146e-07 0.0</pose>
          <geometry>
            <mesh>
              <uri>../meshes/stl/LHTarsus1.stl</uri>
              <scale>1000.0 1000.0 1000.0</scale>
            </mesh>
          </geometry>
        </collision>
        <visual name="LHTarsus1_visual">
          <pose>1.1920921139108032e-07 -2.3841867147211815e-08 -1.4007072479671479e-07 -1.831051221756752e-08 1.4648428248165146e-07 0.0</pose>
          <geometry>
            <mesh>
              <uri>../meshes/stl/LHTarsus1.stl</uri>
              <scale>1000.0 1000.0 1000.0</scale>
            </mesh>
          </geometry>
          <material/>
        </visual>
      </link>
      <link name="LHTarsus2">
        <pose>0.31374093890190125 -0.14321035146713257 -1.2794220447540283 -0.25201255083084106 -0.31872907280921936 0.06054467335343361</pose>
        <inertial>
          <pose>-0.0013344265753403306 0.0022927650716155767 -0.09138864278793335 -1.04288649559021 1.5333384275436401 -0.9174061417579651</pose>
          <mass>4.465595046515482e-07</mass>
          <inertia>
            <ixx>1.5702305993213746e-10</ixx>
            <ixy>0.0</ixy>
            <ixz>0.0</ixz>
            <iyy>1.2414101662298997e-09</iyy>
            <iyz>0.0</iyz>
            <izz>1.2504762418743998e-09</izz>
          </inertia>
        </inertial>
        <collision name="LHTarsus2_collision">
          <pose>0.0 -2.3841867147211815e-08 -2.861021357603022e-07 0.0 1.2207044619572116e-07 -6.103527461220892e-09</pose>
          <geometry>
            <mesh>
              <uri>../meshes/stl/LHTarsus2.stl</uri>
              <scale>1000.0 1000.0 1000.0</scale>
            </mesh>
          </geometry>
        </collision>
        <visual name="LHTarsus2_visual">
          <pose>0.0 -2.3841867147211815e-08 -2.861021357603022e-07 0.0 1.2207044619572116e-07 -6.103527461220892e-09</pose>
          <geometry>
            <mesh>
              <uri>../meshes/stl/LHTarsus2.stl</uri>
              <scale>1000.0 1000.0 1000.0</scale>
            </mesh>
          </geometry>
          <material/>
        </visual>
      </link>
      <link name="LHTarsus3">
        <pose>0.3694056272506714 -0.18450336158275604 -1.4401729106903076 -0.3114085793495178 0.34027427434921265 -0.09924408793449402</pose>
        <inertial>
          <pose>-0.0041370089165866375 0.003209747141227126 -0.04882483184337616 -0.006301043555140495 0.010789243504405022 2.713895320892334</pose>
          <mass>1.717215492644912e-07</mass>
          <inertia>
            <ixx>1.563385979340677e-10</ixx>
            <ixy>0.0</ixy>
            <ixz>0.0</ixz>
            <iyy>1.6050068194399647e-10</iyy>
            <iyz>0.0</iyz>
            <izz>4.2237838036678106e-11</izz>
          </inertia>
        </inertial>
        <collision name="LHTarsus3_collision">
          <pose>1.4305092577160394e-07 -2.3841867147211815e-08 -5.960462790000065e-09 0.0 7.324227624394553e-08 -2.441410806852673e-08</pose>
          <geometry>
            <mesh>
              <uri>../meshes/stl/LHTarsus3.stl</uri>
              <scale>1000.0 1000.0 1000.0</scale>
            </mesh>
          </geometry>
        </collision>
        <visual name="LHTarsus3_visual">
          <pose>1.4305092577160394e-07 -2.3841867147211815e-08 -5.960462790000065e-09 0.0 7.324227624394553e-08 -2.441410806852673e-08</pose>
          <geometry>
            <mesh>
              <uri>../meshes/stl/LHTarsus3.stl</uri>
              <scale>1000.0 1000.0 1000.0</scale>
            </mesh>
          </geometry>
          <material/>
        </visual>
      </link>
      <link name="LHTarsus4">
        <pose>0.33589616417884827 -0.21002864837646484 -1.5272307395935059 -0.5843173265457153 0.9690040946006775 -0.43372851610183716</pose>
        <inertial>
          <pose>-1.192092469182171e-07 -4.7683752057992024e-08 -1.9073465296060022e-07 -2.372246265411377 -1.6625993251800537 -0.4671038091182709</pose>
          <mass>1.1443416496255567e-07</mass>
          <inertia>
            <ixx>2.453657805639322e-11</ixx>
            <ixy>0.0</ixy>
            <ixz>0.0</ixz>
            <iyy>2.480734494565929e-10</iyy>
            <iyz>0.0</iyz>
            <izz>2.5050138085776614e-10</izz>
          </inertia>
        </inertial>
        <collision name="LHTarsus4_collision">
          <pose>-4.768369876728684e-08 -4.7683752057992024e-08 -9.536732648030011e-08 0.0 4.88280917920747e-08 -4.882818060991667e-08</pose>
          <geometry>
            <mesh>
              <uri>../meshes/stl/LHTarsus4.stl</uri>
              <scale>1000.0 1000.0 1000.0</scale>
            </mesh>
          </geometry>
        </collision>
        <visual name="LHTarsus4_visual">
          <pose>-4.768369876728684e-08 -4.7683752057992024e-08 -9.536732648030011e-08 0.0 4.88280917920747e-08 -4.882818060991667e-08</pose>
          <geometry>
            <mesh>
              <uri>../meshes/stl/LHTarsus4.stl</uri>
              <scale>1000.0 1000.0 1000.0</scale>
            </mesh>
          </geometry>
          <material/>
        </visual>
      </link>
      <link name="LHTarsus5">
        <pose>0.27322059869766235 -0.22579741477966309 -1.5618247985839844 1.058811902999878 1.9181243181228638 1.158355474472046</pose>
        <inertial>
          <pose>-0.0017649296205490828 -0.0003561500343494117 -0.05260874703526497 -1.1455327272415161 -1.640228033065796 0.2855782210826874</pose>
          <mass>1.5831647994397422e-07</mass>
          <inertia>
            <ixx>4.283315941445498e-11</ixx>
            <ixy>0.0</ixy>
            <ixz>0.0</ixz>
            <iyy>1.2776930906698356e-10</iyy>
            <iyz>0.0</iyz>
            <izz>1.3616455606807383e-10</izz>
          </inertia>
        </inertial>
        <collision name="LHTarsus5_collision">
          <pose>2.6822094767453564e-08 -9.536752543226612e-08 -1.1920911191509731e-07 9.155249891534822e-09 9.765609121359375e-08 2.441408142317414e-08</pose>
          <geometry>
            <mesh>
              <uri>../meshes/stl/LHTarsus5.stl</uri>
              <scale>1000.0 1000.0 1000.0</scale>
            </mesh>
          </geometry>
        </collision>
        <visual name="LHTarsus5_visual">
          <pose>2.6822094767453564e-08 -9.536752543226612e-08 -1.1920911191509731e-07 9.155249891534822e-09 9.765609121359375e-08 2.441408142317414e-08</pose>
          <geometry>
            <mesh>
              <uri>../meshes/stl/LHTarsus5.stl</uri>
              <scale>1000.0 1000.0 1000.0</scale>
            </mesh>
          </geometry>
          <material/>
        </visual>
      </link>
      <link name="LHTibia">
        <pose>-0.05753597617149353 -0.025476187467575073 -0.41716068983078003 -0.12112925946712494 -0.10742367058992386 0.013050300069153309</pose>
        <inertial>
          <pose>0.023327689617872238 -0.015456466935575008 -0.4177219271659851 2.363767147064209 1.5166335105895996 -0.22312335669994354</pose>
          <mass>4.280437218327039e-06</mass>
          <inertia>
            <ixx>4.54259258271459e-09</ixx>
            <ixy>0.0</ixy>
            <ixz>0.0</ixz>
            <iyy>1.3665711690099893e-07</iyy>
            <iyz>0.0</iyz>
            <izz>1.376334237825959e-07</izz>
          </inertia>
        </inertial>
        <visual name="LHTibia_visual">
          <pose>4.1723179577957126e-08 8.94069973611522e-09 6.183981327012589e-08 -1.2207025612553934e-08 -1.2207051369728106e-08 -1.525882087349828e-09</pose>
          <geometry>
            <mesh>
              <uri>../meshes/stl/LHTibia.stl</uri>
              <scale>1000.0 1000.0 1000.0</scale>
            </mesh>
          </geometry>
          <material/>
        </visual>
      </link>
      <link name="LMCoxa">
        <pose>0.06767531484365463 0.1249004602432251 0.6798474788665771 0.0 -0.0872664526104927 0.0</pose>
        <inertial>
          <pose>-0.001341104507446289 0.004880393389612436 -0.07880996912717819 0.0339132621884346 -1.0169373750686646 -1.662642478942871</pose>
          <mass>3.295969018637448e-06</mass>
          <inertia>
            <ixx>7.744998634072523e-09</ixx>
            <ixy>0.0</ixy>
            <ixz>0.0</ixz>
            <iyy>1.6136943013212866e-08</iyy>
            <iyz>0.0</iyz>
            <izz>1.783195493920484e-08</izz>
          </inertia>
        </inertial>
        <visual name="LMCoxa_visual">
          <pose>5.9604645663569045e-09 0.0 -1.0356307456049763e-07 0.0 2.4414063659605745e-08 0.0</pose>
          <geometry>
            <mesh>
              <uri>../meshes/stl/LMCoxa.stl</uri>
              <scale>1000.0 1000.0 1000.0</scale>
            </mesh>
          </geometry>
          <material/>
        </visual>
      </link>
      <link name="LMCoxa_roll">
        <pose>0.06767532974481583 0.1249004676938057 0.6798474192619324 -0.1300269514322281 -3.7252917195473856e-08 1.629815216119823e-08</pose>
        <inertial>
          <pose>-1.192092469182171e-08 1.1920930909070648e-08 -3.1292444191421964e-08 -0.0 -0.0 0.0</pose>
          <mass>0.0</mass>
          <inertia>
            <ixx>0.0</ixx>
            <ixy>0.0</ixy>
            <ixz>0.0</ixz>
            <iyy>0.0</iyy>
            <iyz>0.0</iyz>
            <izz>0.0</izz>
          </inertia>
        </inertial>
      </link>
      <link name="LMCoxa_yaw">
        <pose>0.06767532229423523 0.1249004527926445 0.6798473000526428 -0.13002698123455048 -9.313226634333205e-09 4.6566133171666024e-09</pose>
        <inertial>
          <pose>-5.960464122267695e-09 1.1920930909070648e-08 -2.086162531611535e-08 -0.0 -0.0 0.0</pose>
          <mass>0.0</mass>
          <inertia>
            <ixx>0.0</ixx>
            <ixy>0.0</ixy>
            <ixz>0.0</ixz>
            <iyy>0.0</iyy>
            <iyz>0.0</iyz>
            <izz>0.0</izz>
          </inertia>
        </inertial>
      </link>
      <link name="LMFemur">
        <pose>0.06745946407318115 0.10157793760299683 0.49990561604499817 -0.1300269365310669 -7.450585570722978e-08 2.793969500203275e-08</pose>
        <inertial>
          <pose>0.023515215143561363 0.0021800759714096785 -0.40512487292289734 -0.8198912739753723 -1.5611728429794312 -1.9618390798568726</pose>
          <mass>8.23079136553737e-06</mass>
          <inertia>
            <ixx>1.3593750670236514e-08</ixx>
            <ixy>0.0</ixy>
            <ixz>0.0</ixz>
            <iyy>4.098601293377078e-07</iyy>
            <iyz>0.0</iyz>
            <izz>4.1009506876853507e-07</izz>
          </inertia>
        </inertial>
        <visual name="LMFemur_visual">
          <pose>5.960460569554016e-09 1.1920930909070648e-08 1.4901166967007384e-09 1.2207033606159712e-08 -1.8599807249941591e-09 4.33039770708632e-10</pose>
          <geometry>
            <mesh>
              <uri>../meshes/stl/LMFemur.stl</uri>
              <scale>1000.0 1000.0 1000.0</scale>
            </mesh>
          </geometry>
          <material/>
        </visual>
      </link>
      <link name="LMFemur_roll">
        <pose>0.06745942682027817 0.10157793760299683 0.49990561604499817 -0.26100292801856995 0.08432511985301971 -0.022492390125989914</pose>
        <inertial>
          <pose>-2.3841838725502384e-08 -5.960465898624534e-09 -8.94070240065048e-08 -0.0 -0.0 0.0</pose>
          <mass>0.0</mass>
          <inertia>
            <ixx>0.0</ixx>
            <ixy>0.0</ixy>
            <ixz>0.0</ixz>
            <iyy>0.0</iyy>
            <iyz>0.0</iyz>
            <izz>0.0</izz>
          </inertia>
        </inertial>
      </link>
      <link name="LMTarsus1">
        <pose>-0.05969071388244629 -0.26898884773254395 -0.8972017765045166 -0.5170009732246399 -0.6945066452026367 0.3612196743488312</pose>
        <inertial>
          <pose>-0.00750884972512722 0.00019428733503445983 -0.1536024659872055 -2.4108965396881104 -1.5081813335418701 -0.3244836628437042</pose>
          <mass>6.662969614149409e-07</mass>
          <inertia>
            <ixx>2.1839893140801834e-10</ixx>
            <ixy>0.0</ixy>
            <ixz>0.0</ixz>
            <iyy>4.796224773051595e-09</iyy>
            <iyz>0.0</iyz>
            <izz>4.8330252433213445e-09</izz>
          </inertia>
        </inertial>
        <collision name="LMTarsus1_collision">
          <pose>-1.192092824453539e-08 0.0 -6.25848599611345e-08 -4.882810245021574e-08 -4.8828113108356774e-08 2.4414067212319424e-08</pose>
          <geometry>
            <mesh>
              <uri>../meshes/stl/LMTarsus1.stl</uri>
              <scale>1000.0 1000.0 1000.0</scale>
            </mesh>
          </geometry>
        </collision>
        <visual name="LMTarsus1_visual">
          <pose>-1.192092824453539e-08 0.0 -6.25848599611345e-08 -4.882810245021574e-08 -4.8828113108356774e-08 2.4414067212319424e-08</pose>
          <geometry>
            <mesh>
              <uri>../meshes/stl/LMTarsus1.stl</uri>
              <scale>1000.0 1000.0 1000.0</scale>
            </mesh>
          </geometry>
          <material/>
        </visual>
      </link>
      <link name="LMTarsus2">
        <pose>0.14524096250534058 -0.3475325405597687 -1.0933350324630737 -0.5343126654624939 0.2402595579624176 -0.10118456184864044</pose>
        <inertial>
          <pose>-0.004910679534077644 0.000820469984319061 -0.0791720598936081 -0.5143923163414001 1.5483042001724243 1.876367211341858</pose>
          <mass>2.988951419617774e-07</mass>
          <inertia>
            <ixx>8.096322359093499e-11</ixx>
            <ixy>0.0</ixy>
            <ixz>0.0</ixz>
            <iyy>6.074880758643851e-10</iyy>
            <iyz>0.0</iyz>
            <izz>6.12933830524174e-10</izz>
          </inertia>
        </inertial>
        <collision name="LMTarsus2_collision">
          <pose>-9.536734779658218e-08 0.0 -1.430512668321171e-07 -9.765631148184184e-08 4.88282090316261e-08 1.2207043376122328e-08</pose>
          <geometry>
            <mesh>
              <uri>../meshes/stl/LMTarsus2.stl</uri>
              <scale>1000.0 1000.0 1000.0</scale>
            </mesh>
          </geometry>
        </collision>
        <visual name="LMTarsus2_visual">
          <pose>-9.536734779658218e-08 0.0 -1.430512668321171e-07 -9.765631148184184e-08 4.88282090316261e-08 1.2207043376122328e-08</pose>
          <geometry>
            <mesh>
              <uri>../meshes/stl/LMTarsus2.stl</uri>
              <scale>1000.0 1000.0 1000.0</scale>
            </mesh>
          </geometry>
          <material/>
        </visual>
      </link>
      <link name="LMTarsus3">
        <pose>0.10453993082046509 -0.42495593428611755 -1.226311445236206 -1.2769254446029663 0.9849627614021301 -1.0397244691848755</pose>
        <inertial>
          <pose>-0.0020941037219017744 0.0020650867372751236 -0.044653430581092834 -1.5194878578186035 -1.6493253707885742 -0.22837398946285248</pose>
          <mass>1.49359671801039e-07</mass>
          <inertia>
            <ixx>3.552360232276329e-11</ixx>
            <ixy>0.0</ixy>
            <ixz>0.0</ixz>
            <iyy>1.174319056335369e-10</iyy>
            <iyz>0.0</iyz>
            <izz>1.2034080842228002e-10</izz>
          </inertia>
        </inertial>
        <collision name="LMTarsus3_collision">
          <pose>-3.099444256804418e-07 2.3841861818141297e-08 -3.8742999208807305e-07 -3.051756181093879e-08 2.4414028132468957e-08 0.0</pose>
          <geometry>
            <mesh>
              <uri>../meshes/stl/LMTarsus3.stl</uri>
              <scale>1000.0 1000.0 1000.0</scale>
            </mesh>
          </geometry>
        </collision>
        <visual name="LMTarsus3_visual">
          <pose>-3.099444256804418e-07 2.3841861818141297e-08 -3.8742999208807305e-07 -3.051756181093879e-08 2.4414028132468957e-08 0.0</pose>
          <geometry>
            <mesh>
              <uri>../meshes/stl/LMTarsus3.stl</uri>
              <scale>1000.0 1000.0 1000.0</scale>
            </mesh>
          </geometry>
          <material/>
        </visual>
      </link>
      <link name="LMTarsus4">
        <pose>0.01959407329559326 -0.4499797821044922 -1.240815281867981 0.5739695429801941 2.5461456775665283 0.6367456912994385</pose>
        <inertial>
          <pose>-1.9073497981025866e-07 -7.152556946721234e-08 -3.0994422672847577e-07 1.032448172569275 -1.6772009134292603 -0.291657954454422</pose>
          <mass>8.690413245737014e-08</mass>
          <inertia>
            <ixx>1.8116226516446115e-11</ixx>
            <ixy>0.0</ixy>
            <ixz>0.0</ixz>
            <iyy>1.2203751240184389e-10</iyy>
            <iyz>0.0</iyz>
            <izz>1.2359737747020198e-10</izz>
          </inertia>
        </inertial>
        <collision name="LMTarsus4_collision">
          <pose>-1.9073497981025866e-07 -9.536742595628311e-08 -2.98023280720372e-07 -7.324221229509931e-08 4.8828109555643096e-08 0.0</pose>
          <geometry>
            <mesh>
              <uri>../meshes/stl/LMTarsus4.stl</uri>
              <scale>1000.0 1000.0 1000.0</scale>
            </mesh>
          </geometry>
        </collision>
        <visual name="LMTarsus4_visual">
          <pose>-1.9073497981025866e-07 -9.536742595628311e-08 -2.98023280720372e-07 -7.324221229509931e-08 4.8828109555643096e-08 0.0</pose>
          <geometry>
            <mesh>
              <uri>../meshes/stl/LMTarsus4.stl</uri>
              <scale>1000.0 1000.0 1000.0</scale>
            </mesh>
          </geometry>
          <material/>
        </visual>
      </link>
      <link name="LMTarsus5">
        <pose>-0.024950921535491943 -0.4400888681411743 -1.1969738006591797 0.35905733704566956 -2.8248214721679688 0.13660211861133575</pose>
        <inertial>
          <pose>-0.0010364530608057976 -0.0005474089994095266 -0.04305513948202133 1.6952461004257202 -1.6717164516448975 0.14511638879776</pose>
          <mass>1.4474194312568478e-07</mass>
          <inertia>
            <ixx>3.399446533534265e-11</ixx>
            <ixy>0.0</ixy>
            <ixz>0.0</ixz>
            <iyy>1.171272490903981e-10</iyy>
            <iyz>0.0</iyz>
            <izz>1.2253828172964362e-10</izz>
          </inertia>
        </inertial>
        <collision name="LMTarsus5_collision">
          <pose>-1.6689297410721338e-07 0.0 -2.622607837565738e-07 0.0 -2.4414099186742533e-08 2.4414063659605745e-08</pose>
          <geometry>
            <mesh>
              <uri>../meshes/stl/LMTarsus5.stl</uri>
              <scale>1000.0 1000.0 1000.0</scale>
            </mesh>
          </geometry>
        </collision>
        <visual name="LMTarsus5_visual">
          <pose>-1.6689297410721338e-07 0.0 -2.622607837565738e-07 0.0 -2.4414099186742533e-08 2.4414063659605745e-08</pose>
          <geometry>
            <mesh>
              <uri>../meshes/stl/LMTarsus5.stl</uri>
              <scale>1000.0 1000.0 1000.0</scale>
            </mesh>
          </geometry>
          <material/>
        </visual>
      </link>
      <link name="LMTibia">
        <pose>-0.0018077939748764038 -0.09857501089572906 -0.25460177659988403 -0.26100292801856995 0.08432509750127792 -0.022492382675409317</pose>
        <inertial>
          <pose>0.022280124947428703 0.003726399503648281 -0.3737770915031433 -1.2372270822525024 1.5140249729156494 0.30270856618881226</pose>
          <mass>3.631542037586609e-06</mass>
          <inertia>
            <ixx>2.9065580702067685e-09</ixx>
            <ixy>0.0</ixy>
            <ixz>0.0</ixz>
            <iyy>1.3521047568017022e-07</iyy>
            <iyz>0.0</iyz>
            <izz>1.3434352224012308e-07</izz>
          </inertia>
        </inertial>
        <visual name="LMTibia_visual">
          <pose>-3.2037462460721144e-08 2.980232594040899e-08 8.94070240065048e-09 0.0 -6.103526128953263e-09 0.0</pose>
          <geometry>
            <mesh>
              <uri>../meshes/stl/LMTibia.stl</uri>
              <scale>1000.0 1000.0 1000.0</scale>
            </mesh>
          </geometry>
          <material/>
        </visual>
      </link>
      <link name="LWing">
        <pose>-0.09160558134317398 0.36983221769332886 1.3241827487945557 1.1233777286179247e-07 0.5934117436408997 -1.570796012878418</pose>
        <inertial>
          <pose>-0.11281491816043854 1.0776904821395874 0.08102906495332718 0.023574000224471092 -0.05251660197973251 1.6804596185684204</pose>
          <mass>2.500079241447992e-06</mass>
          <inertia>
            <ixx>1.7098524745415547e-07</ixx>
            <ixy>0.0</ixy>
            <ixz>0.0</ixz>
            <iyy>8.043481307165544e-07</iyy>
            <iyz>0.0</iyz>
            <izz>9.658349993768159e-07</izz>
          </inertia>
        </inertial>
        <visual name="LWing_visual">
          <pose>1.907349229668398e-07 -3.5762788286319847e-08 0.0 3.2234599434133315e-09 -4.882813087192517e-08 0.0</pose>
          <geometry>
            <mesh>
              <uri>../meshes/stl/LWing.stl</uri>
              <scale>1000.0 1000.0 1000.0</scale>
            </mesh>
          </geometry>
          <material/>
        </visual>
      </link>
      <link name="LWing_roll">
        <pose>-0.09160565584897995 0.3698323369026184 1.324182152748108 0.0 -0.0 1.5707964897155762</pose>
        <inertial>
          <pose>4.7683716530855236e-08 -5.9604645663569045e-09 9.536743306171047e-08 -0.0 -0.0 0.0</pose>
          <mass>0.0</mass>
          <inertia>
            <ixx>0.0</ixx>
            <ixy>0.0</ixy>
            <ixz>0.0</ixz>
            <iyy>0.0</iyy>
            <iyz>0.0</iyz>
            <izz>0.0</izz>
          </inertia>
        </inertial>
      </link>
      <link name="LWing_yaw">
        <pose>-0.09160563349723816 0.3698323369026184 1.3241825103759766 0.2967059314250946 -5.6331671771658876e-08 2.2500550755921722e-07</pose>
        <inertial>
          <pose>8.940696716308594e-08 0.0 9.536745437799254e-08 -0.0 -0.0 0.0</pose>
          <mass>0.0</mass>
          <inertia>
            <ixx>0.0</ixx>
            <ixy>0.0</ixy>
            <ixz>0.0</ixz>
            <iyy>0.0</iyy>
            <iyz>0.0</iyz>
            <izz>0.0</izz>
          </inertia>
        </inertial>
      </link>
      <link name="prismatic_support_1">
        <pose>0.0 0.0 0.0 0.0 -0.0 0.0</pose>
        <inertial>
          <pose>0.0 0.0 0.0 -0.0 -0.0 0.0</pose>
          <mass>0.0</mass>
          <inertia>
            <ixx>0.0</ixx>
            <ixy>0.0</ixy>
            <ixz>0.0</ixz>
            <iyy>0.0</iyy>
            <iyz>0.0</iyz>
            <izz>0.0</izz>
          </inertia>
        </inertial>
      </link>
      <link name="prismatic_support_2">
        <pose>0.0 0.0 0.0 0.0 -0.0 0.0</pose>
        <inertial>
          <pose>0.0 0.0 0.0 -0.0 -0.0 0.0</pose>
          <mass>0.0</mass>
          <inertia>
            <ixx>0.0</ixx>
            <ixy>0.0</ixy>
            <ixz>0.0</ixz>
            <iyy>0.0</iyy>
            <iyz>0.0</iyz>
            <izz>0.0</izz>
          </inertia>
        </inertial>
      </link>
      <link name="RAntenna">
        <pose>0.9481761455535889 -0.06800426542758942 1.2725656032562256 -0.5759587287902832 7.450578465295621e-08 6.351129067105887e-10</pose>
        <inertial>
          <pose>0.05092441290616989 -0.013293614611029625 -0.1115555465221405 -1.5525360107421875 -1.41914963722229 -0.3158208429813385</pose>
          <mass>1.7777381698425424e-06</mass>
          <inertia>
            <ixx>4.8019352077394176e-09</ixx>
            <ixy>0.0</ixy>
            <ixz>0.0</ixz>
            <iyy>1.2519733113236938e-08</iyy>
            <iyz>0.0</iyz>
            <izz>1.0261991696422303e-08</izz>
          </inertia>
        </inertial>
        <visual name="RAntenna_visual">
          <pose>9.53674614834199e-08 1.788139627478813e-07 1.2218954736908927e-07 0.0 5.899165600453671e-09 -5.8007505465695886e-09</pose>
          <geometry>
            <mesh>
              <uri>../meshes/stl/RAntenna.stl</uri>
              <scale>1000.0 1000.0 1000.0</scale>
            </mesh>
          </geometry>
          <material/>
        </visual>
      </link>
      <link name="REye">
        <pose>0.7419561147689819 -5.634857416225714e-07 1.2583277225494385 0.0 3.7252892326478104e-08 0.0</pose>
        <inertial>
          <pose>-0.01288786344230175 -0.317592054605484 -0.030690938234329224 0.2250286191701889 -0.13706368207931519 -1.9546054601669312</pose>
          <mass>8.241895909613487e-06</mass>
          <inertia>
            <ixx>1.7195932737877324e-07</ixx>
            <ixy>0.0</ixy>
            <ixz>0.0</ixz>
            <iyy>1.1167877923308259e-07</iyy>
            <iyz>0.0</iyz>
            <izz>7.44113559143184e-08</izz>
          </inertia>
        </inertial>
        <visual name="REye_visual">
          <pose>-4.768373074170995e-08 4.547473576627277e-14 -2.5846236439974746e-07 0.0 -6.73532207784433e-09 0.0</pose>
          <geometry>
            <mesh>
              <uri>../meshes/stl/REye.stl</uri>
              <scale>1000.0 1000.0 1000.0</scale>
            </mesh>
          </geometry>
          <material/>
        </visual>
      </link>
      <link name="RFCoxa">
        <pose>0.41799992322921753 -0.2700002193450928 1.0799976587295532 0.0 -0.0 0.34906575083732605</pose>
        <inertial>
          <pose>0.002980828983709216 0.03152225911617279 -0.25312432646751404 0.04575847089290619 -0.049276337027549744 -0.5402534604072571</pose>
          <mass>5.741706163530321e-06</mass>
          <inertia>
            <ixx>6.08101486746388e-08</ixx>
            <ixy>0.0</ixy>
            <ixz>0.0</ixz>
            <iyy>5.720229808199986e-08</iyy>
            <iyz>0.0</iyz>
            <izz>1.4003978171789712e-08</izz>
          </inertia>
        </inertial>
        <visual name="RFCoxa_visual">
          <pose>0.0 7.152559078349441e-08 0.0 0.0 -0.0 4.882812021378413e-08</pose>
          <geometry>
            <mesh>
              <uri>../meshes/stl/RFCoxa.stl</uri>
              <scale>1000.0 1000.0 1000.0</scale>
            </mesh>
          </geometry>
          <material/>
        </visual>
      </link>
      <link name="RFCoxa_roll">
        <pose>0.41799989342689514 -0.27000051736831665 1.0799976587295532 0.0 -0.0 0.17453287541866302</pose>
        <inertial>
          <pose>4.7683720083568915e-08 9.536744016713783e-08 0.0 -0.0 -0.0 0.0</pose>
          <mass>0.0</mass>
          <inertia>
            <ixx>0.0</ixx>
            <ixy>0.0</ixy>
            <ixz>0.0</ixz>
            <iyy>0.0</iyy>
            <iyz>0.0</iyz>
            <izz>0.0</izz>
          </inertia>
        </inertial>
      </link>
      <link name="RFCoxa_yaw">
        <pose>0.41799992322921753 -0.2700003683567047 1.0799976587295532 0.0 -0.0 0.34906578063964844</pose>
        <inertial>
          <pose>7.152559078349441e-08 1.1920931797249068e-07 0.0 -0.0 -0.0 0.0</pose>
          <mass>0.0</mass>
          <inertia>
            <ixx>0.0</ixx>
            <ixy>0.0</ixy>
            <ixz>0.0</ixz>
            <iyy>0.0</iyy>
            <iyz>0.0</iyz>
            <izz>0.0</izz>
          </inertia>
        </inertial>
      </link>
      <link name="RFFemur">
        <pose>0.41799986362457275 -0.270000159740448 0.6545186638832092 0.0 -0.0 0.34906575083732605</pose>
        <inertial>
          <pose>-0.019857697188854218 0.006748510990291834 -0.3594456613063812 -0.07037092000246048 -1.653964638710022 1.9682725667953491</pose>
          <mass>7.99213320458308e-06</mass>
          <inertia>
            <ixx>1.4380669374311288e-08</ixx>
            <ixy>0.0</ixy>
            <ixz>0.0</ixz>
            <iyy>2.7248460324668107e-07</iyy>
            <iyz>0.0</iyz>
            <izz>2.7485418460854175e-07</izz>
          </inertia>
        </inertial>
        <visual name="RFFemur_visual">
          <pose>-7.152559078349441e-08 2.3841863594498136e-08 9.536743306171047e-08 0.0 -0.0 4.882812021378413e-08</pose>
          <geometry>
            <mesh>
              <uri>../meshes/stl/RFFemur.stl</uri>
              <scale>1000.0 1000.0 1000.0</scale>
            </mesh>
          </geometry>
          <material/>
        </visual>
      </link>
      <link name="RFFemur_roll">
        <pose>0.417999804019928 -0.27000007033348083 0.6545187830924988 0.0 -0.0 0.5235986709594727</pose>
        <inertial>
          <pose>0.0 9.536746858884726e-08 4.7683716530855236e-08 -0.0 -0.0 0.0</pose>
          <mass>0.0</mass>
          <inertia>
            <ixx>0.0</ixx>
            <ixy>0.0</ixy>
            <ixz>0.0</ixz>
            <iyy>0.0</iyy>
            <iyz>0.0</iyz>
            <izz>0.0</izz>
          </inertia>
        </inertial>
      </link>
      <link name="RFTarsus1">
        <pose>0.41799986362457275 -0.26999980211257935 -0.5691338181495667 -1.6817358616805222e-10 -0.6806783080101013 0.6981316208839417</pose>
        <inertial>
          <pose>-0.004590428434312344 0.009429840371012688 -0.12338640540838242 2.4326164722442627 -1.5347644090652466 0.2797347903251648</pose>
          <mass>5.902334030056455e-07</mass>
          <inertia>
            <ixx>2.1051963591762187e-10</ixx>
            <ixy>0.0</ixy>
            <ixz>0.0</ixz>
            <iyy>2.6598972156863696e-09</iyy>
            <iyz>0.0</iyz>
            <izz>2.6763323997498303e-09</izz>
          </inertia>
        </inertial>
        <collision name="RFTarsus1_collision">
          <pose>1.1920930020892229e-08 0.0 7.152557657263969e-08 1.1783499509476769e-08 -0.0 -5.858971974248561e-08</pose>
          <geometry>
            <mesh>
              <uri>../meshes/stl/RFTarsus1.stl</uri>
              <scale>1000.0 1000.0 1000.0</scale>
            </mesh>
          </geometry>
        </collision>
        <visual name="RFTarsus1_visual">
          <pose>1.1920930020892229e-08 0.0 7.152557657263969e-08 1.1783499509476769e-08 -0.0 -5.858971974248561e-08</pose>
          <geometry>
            <mesh>
              <uri>../meshes/stl/RFTarsus1.stl</uri>
              <scale>1000.0 1000.0 1000.0</scale>
            </mesh>
          </geometry>
          <material/>
        </visual>
      </link>
      <link name="RFTarsus2">
        <pose>0.5266759991645813 -0.17880968749523163 -0.7443245649337769 -5.6197116293787985e-08 -1.4901158351676713e-07 0.8726645708084106</pose>
        <inertial>
          <pose>-0.0012889865320175886 0.005323697347193956 -0.0892031118273735 -0.7475863099098206 1.5205036401748657 -0.06143252179026604</pose>
          <mass>2.6589763376152175e-07</mass>
          <inertia>
            <ixx>6.580080499487646e-11</ixx>
            <ixy>0.0</ixy>
            <ixz>0.0</ixz>
            <iyy>5.158322716307566e-10</iyy>
            <iyz>0.0</iyz>
            <izz>5.066425364501285e-10</izz>
          </inertia>
        </inertial>
        <collision name="RFTarsus2_collision">
          <pose>-7.152559078349441e-08 0.0 -1.0685141660360387e-07 1.0553039331284708e-08 -6.461143442493267e-08 -4.9044338435008574e-15</pose>
          <geometry>
            <mesh>
              <uri>../meshes/stl/RFTarsus2.stl</uri>
              <scale>1000.0 1000.0 1000.0</scale>
            </mesh>
          </geometry>
        </collision>
        <visual name="RFTarsus2_visual">
          <pose>-7.152559078349441e-08 0.0 -1.0685141660360387e-07 1.0553039331284708e-08 -6.461143442493267e-08 -4.9044338435008574e-15</pose>
          <geometry>
            <mesh>
              <uri>../meshes/stl/RFTarsus2.stl</uri>
              <scale>1000.0 1000.0 1000.0</scale>
            </mesh>
          </geometry>
          <material/>
        </visual>
      </link>
      <link name="RFTarsus3">
        <pose>0.5266761779785156 -0.17880958318710327 -0.8980008959770203 0.13970129191875458 0.6684359312057495 1.0957773923873901</pose>
        <inertial>
          <pose>-0.0010803461773321033 0.0034553539007902145 -0.059404920786619186 -1.238084316253662 1.4883235692977905 0.4349120259284973</pose>
          <mass>1.5048445801063186e-07</mass>
          <inertia>
            <ixx>3.169918271661641e-11</ixx>
            <ixy>0.0</ixy>
            <ixz>0.0</ixz>
            <iyy>1.31822647337979e-10</iyy>
            <iyz>0.0</iyz>
            <izz>1.280254472124895e-10</izz>
          </inertia>
        </inertial>
        <collision name="RFTarsus3_collision">
          <pose>-4.7683720083568915e-08 9.53674614834199e-08 3.5762788286319847e-08 4.2724604298882696e-08 -4.882813442463885e-08 -6.103518579436695e-09</pose>
          <geometry>
            <mesh>
              <uri>../meshes/stl/RFTarsus3.stl</uri>
              <scale>1000.0 1000.0 1000.0</scale>
            </mesh>
          </geometry>
        </collision>
        <visual name="RFTarsus3_visual">
          <pose>-4.7683720083568915e-08 9.53674614834199e-08 3.5762788286319847e-08 4.2724604298882696e-08 -4.882813442463885e-08 -6.103518579436695e-09</pose>
          <geometry>
            <mesh>
              <uri>../meshes/stl/RFTarsus3.stl</uri>
              <scale>1000.0 1000.0 1000.0</scale>
            </mesh>
          </geometry>
          <material/>
        </visual>
      </link>
      <link name="RFTarsus4">
        <pose>0.486830472946167 -0.226296067237854 -0.9745512008666992 0.9117425680160522 1.2139229774475098 1.9277427196502686</pose>
        <inertial>
          <pose>0.000869559939019382 0.0014741425402462482 -0.05002078041434288 -2.7275757789611816 1.4870363473892212 0.4085143804550171</pose>
          <mass>1.1769954845621714e-07</mass>
          <inertia>
            <ixx>2.2466920526005993e-11</ixx>
            <ixy>0.0</ixy>
            <ixz>0.0</ixz>
            <iyy>7.489487270185947e-11</iyy>
            <iyz>0.0</iyz>
            <izz>7.742830982406114e-11</izz>
          </inertia>
        </inertial>
        <collision name="RFTarsus4_collision">
          <pose>-2.384184938364342e-08 1.4305119577784353e-07 9.536743306171047e-08 6.103513694455387e-09 -8.544926544118425e-08 -2.4414084975887818e-08</pose>
          <geometry>
            <mesh>
              <uri>../meshes/stl/RFTarsus4.stl</uri>
              <scale>1000.0 1000.0 1000.0</scale>
            </mesh>
          </geometry>
        </collision>
        <visual name="RFTarsus4_visual">
          <pose>-2.384184938364342e-08 1.4305119577784353e-07 9.536743306171047e-08 6.103513694455387e-09 -8.544926544118425e-08 -2.4414084975887818e-08</pose>
          <geometry>
            <mesh>
              <uri>../meshes/stl/RFTarsus4.stl</uri>
              <scale>1000.0 1000.0 1000.0</scale>
            </mesh>
          </geometry>
          <material/>
        </visual>
      </link>
      <link name="RFTarsus5">
        <pose>0.4398167133331299 -0.2971195578575134 -0.9931677579879761 -0.783502459526062 2.211385488510132 0.2893138527870178</pose>
        <inertial>
          <pose>0.002577243372797966 0.0008895400678738952 -0.05208313837647438 -1.357399582862854 -1.678462028503418 0.10700014233589172</pose>
          <mass>1.4544445851261665e-07</mass>
          <inertia>
            <ixx>3.336259558840379e-11</ixx>
            <ixy>0.0</ixy>
            <ixz>0.0</ixz>
            <iyy>1.1437004582527995e-10</iyy>
            <iyz>0.0</iyz>
            <izz>1.2046816516483323e-10</izz>
          </inertia>
        </inertial>
        <collision name="RFTarsus5_collision">
          <pose>-2.8610207891688333e-07 9.536746858884726e-08 -7.152556236178498e-08 -4.882809889750206e-08 -9.765631148184184e-08 2.4414090304958336e-08</pose>
          <geometry>
            <mesh>
              <uri>../meshes/stl/RFTarsus5.stl</uri>
              <scale>1000.0 1000.0 1000.0</scale>
            </mesh>
          </geometry>
        </collision>
        <visual name="RFTarsus5_visual">
          <pose>-2.8610207891688333e-07 9.536746858884726e-08 -7.152556236178498e-08 -4.882809889750206e-08 -9.765631148184184e-08 2.4414090304958336e-08</pose>
          <geometry>
            <mesh>
              <uri>../meshes/stl/RFTarsus5.stl</uri>
              <scale>1000.0 1000.0 1000.0</scale>
            </mesh>
          </geometry>
          <material/>
        </visual>
      </link>
      <link name="RFTibia">
        <pose>0.41799983382225037 -0.26999998092651367 -0.050721097737550735 0.0 -0.0 0.5235986709594727</pose>
        <inertial>
          <pose>0.011396961286664009 0.003588820807635784 -0.29302605986595154 -0.11941171437501907 1.6242854595184326 2.296193838119507</pose>
          <mass>2.626834378398769e-06</mass>
          <inertia>
            <ixx>2.0302173279315666e-09</ixx>
            <ixy>0.0</ixy>
            <ixz>0.0</ixz>
            <iyy>5.494782707177859e-08</iyy>
            <iyz>0.0</iyz>
            <izz>5.5435775286126054e-08</izz>
          </inertia>
        </inertial>
        <visual name="RFTibia_visual">
          <pose>0.0 4.768373429442363e-08 0.0 0.0 -0.0 4.882812021378413e-08</pose>
          <geometry>
            <mesh>
              <uri>../meshes/stl/RFTibia.stl</uri>
              <scale>1000.0 1000.0 1000.0</scale>
            </mesh>
          </geometry>
          <material/>
        </visual>
      </link>
      <link name="RHaltere">
        <pose>-0.25896796584129333 -0.213557168841362 0.9370102286338806 0.0 -0.0 0.0</pose>
        <inertial>
          <pose>-0.007629299070686102 -0.20604589581489563 -0.0028711319901049137 -1.5649619102478027 0.34976229071617126 -0.0024066928308457136</pose>
          <mass>1.41608730082593e-06</mass>
          <inertia>
            <ixx>1.4022406845010752e-08</ixx>
            <ixy>0.0</ixy>
            <ixz>0.0</ixz>
            <iyy>1.3647689510825423e-08</iyy>
            <iyz>0.0</iyz>
            <izz>1.972686903409018e-09</izz>
          </inertia>
        </inertial>
        <visual name="RHaltere_visual">
          <pose>-2.3841858265427618e-08 -2.3841858265427618e-08 0.0 0.0 -0.0 0.0</pose>
          <geometry>
            <mesh>
              <uri>../meshes/stl/RHaltere.stl</uri>
              <scale>1000.0 1000.0 1000.0</scale>
            </mesh>
          </geometry>
          <material/>
        </visual>
      </link>
      <link name="RHaltere_roll">
        <pose>-0.2589678466320038 -0.21355724334716797 0.9370102286338806 0.0 -0.0 0.0</pose>
        <inertial>
          <pose>-4.7683716530855236e-08 2.3841858265427618e-08 0.0 -0.0 -0.0 0.0</pose>
          <mass>0.0</mass>
          <inertia>
            <ixx>0.0</ixx>
            <ixy>0.0</ixy>
            <ixz>0.0</ixz>
            <iyy>0.0</iyy>
            <iyz>0.0</iyz>
            <izz>0.0</izz>
          </inertia>
        </inertial>
      </link>
      <link name="RHaltere_yaw">
        <pose>-0.25896790623664856 -0.2135571986436844 0.9370102286338806 0.0 -0.0 0.0</pose>
        <inertial>
          <pose>-7.152557657263969e-08 4.7683716530855236e-08 0.0 -0.0 -0.0 0.0</pose>
          <mass>0.0</mass>
          <inertia>
            <ixx>0.0</ixx>
            <ixy>0.0</ixy>
            <ixz>0.0</ixz>
            <iyy>0.0</iyy>
            <iyz>0.0</iyz>
            <izz>0.0</izz>
          </inertia>
        </inertial>
      </link>
      <link name="RHCoxa">
        <pose>-0.14771801233291626 -0.08699406683444977 0.6072231531143188 0.0 0.10821041464805603 0.0</pose>
        <inertial>
          <pose>-0.0037282460834831 -0.020860403776168823 -0.10102212429046631 0.19146551191806793 -1.2239435911178589 1.7328894138336182</pose>
          <mass>3.2548946367291556e-06</mass>
          <inertia>
            <ixx>8.053217910675667e-09</ixx>
            <ixy>0.0</ixy>
            <ixz>0.0</ixz>
            <iyy>1.3522685965060012e-08</iyy>
            <iyz>0.0</iyz>
            <izz>1.5296057403642717e-08</izz>
          </inertia>
        </inertial>
        <visual name="RHCoxa_visual">
          <pose>1.192092735635697e-08 -5.9604645663569045e-09 -5.3644171771338733e-08 0.0 1.2207031829802872e-08 0.0</pose>
          <geometry>
            <mesh>
              <uri>../meshes/stl/RHCoxa.stl</uri>
              <scale>1000.0 1000.0 1000.0</scale>
            </mesh>
          </geometry>
          <material/>
        </visual>
      </link>
      <link name="RHCoxa_roll">
        <pose>-0.14771787822246552 -0.08699409663677216 0.6072232127189636 0.06021381914615631 1.8626465703164286e-08 2.3283082128955357e-09</pose>
        <inertial>
          <pose>5.960460214282648e-08 -1.7881395919516763e-08 7.636845111846924e-08 -0.0 -0.0 0.0</pose>
          <mass>0.0</mass>
          <inertia>
            <ixx>0.0</ixx>
            <ixy>0.0</ixy>
            <ixz>0.0</ixz>
            <iyy>0.0</iyy>
            <iyz>0.0</iyz>
            <izz>0.0</izz>
          </inertia>
        </inertial>
      </link>
      <link name="RHCoxa_yaw">
        <pose>-0.14771798253059387 -0.08699408173561096 0.6072232127189636 0.060213856399059296 -1.862645682138009e-08 -1.1641535513362555e-09</pose>
        <inertial>
          <pose>5.960462701182223e-08 -1.1920929132713809e-08 -1.1920929132713809e-08 -0.0 -0.0 0.0</pose>
          <mass>0.0</mass>
          <inertia>
            <ixx>0.0</ixx>
            <ixy>0.0</ixy>
            <ixz>0.0</ixz>
            <iyy>0.0</iyy>
            <iyz>0.0</iyz>
            <izz>0.0</izz>
          </inertia>
        </inertial>
      </link>
      <link name="RHFemur">
        <pose>-0.14779604971408844 -0.07457725703716278 0.4081929326057434 0.06021381914615631 9.313236404295822e-08 6.984927303221866e-09</pose>
        <inertial>
          <pose>0.033161234110593796 0.018143992871046066 -0.43908920884132385 0.0770643875002861 1.5976946353912354 2.2735719680786133</pose>
          <mass>1.1113711231749002e-05</mass>
          <inertia>
            <ixx>2.672350841235894e-08</ixx>
            <ixy>0.0</ixy>
            <ixz>0.0</ixz>
            <iyy>5.20648576934964e-07</iyy>
            <iyz>0.0</iyz>
            <izz>5.279008752925113e-07</izz>
          </inertia>
        </inertial>
        <visual name="RHFemur_visual">
          <pose>2.3841831620075027e-08 0.0 -4.17232506322307e-08 1.831054241563379e-08 -9.325617611466441e-09 -1.6583634465661135e-09</pose>
          <geometry>
            <mesh>
              <uri>../meshes/stl/RHFemur.stl</uri>
              <scale>1000.0 1000.0 1000.0</scale>
            </mesh>
          </geometry>
          <material/>
        </visual>
      </link>
      <link name="RHFemur_roll">
        <pose>-0.14779594540596008 -0.07457724958658218 0.4081929326057434 0.12112926691770554 -0.10742367804050446 -0.013050301931798458</pose>
        <inertial>
          <pose>7.152547709665669e-08 1.1920933573605907e-08 -3.4272666482593195e-08 -0.0 -0.0 0.0</pose>
          <mass>0.0</mass>
          <inertia>
            <ixx>0.0</ixx>
            <ixy>0.0</ixy>
            <ixz>0.0</ixz>
            <iyy>0.0</iyy>
            <iyz>0.0</iyz>
            <izz>0.0</izz>
          </inertia>
        </inertial>
      </link>
      <link name="RHTarsus1">
        <pose>0.016268521547317505 0.10755318403244019 -1.0926896333694458 0.32668283581733704 -0.9778951406478882 -0.267324298620224</pose>
        <inertial>
          <pose>-0.0030510167125612497 -0.0029546867590397596 -0.1676483154296875 2.60998272895813 -1.5582249164581299 0.302709698677063</pose>
          <mass>1.3250065372293525e-06</mass>
          <inertia>
            <ixx>7.359396061907103e-10</ixx>
            <ixy>0.0</ixy>
            <ixz>0.0</ixz>
            <iyy>1.384507470715152e-08</iyy>
            <iyz>0.0</iyz>
            <izz>1.3962129324698023e-08</izz>
          </inertia>
        </inertial>
        <collision name="RHTarsus1_collision">
          <pose>-1.9222486002945516e-07 -1.1920933573605907e-08 7.450570649325527e-08 1.831051221756752e-08 1.4648428248165146e-07 0.0</pose>
          <geometry>
            <mesh>
              <uri>../meshes/stl/RHTarsus1.stl</uri>
              <scale>1000.0 1000.0 1000.0</scale>
            </mesh>
          </geometry>
        </collision>
        <visual name="RHTarsus1_visual">
          <pose>-1.9222486002945516e-07 -1.1920933573605907e-08 7.450570649325527e-08 1.831051221756752e-08 1.4648428248165146e-07 0.0</pose>
          <geometry>
            <mesh>
              <uri>../meshes/stl/RHTarsus1.stl</uri>
              <scale>1000.0 1000.0 1000.0</scale>
            </mesh>
          </geometry>
          <material/>
        </visual>
      </link>
      <link name="RHTarsus2">
        <pose>0.3135308027267456 0.14346317946910858 -1.2791647911071777 0.25201255083084106 -0.31872907280921936 -0.06054467335343361</pose>
        <inertial>
          <pose>-0.0011621455196291208 -0.0024351964239031076 -0.09136324375867844 0.4230789542198181 1.5384026765823364 0.571819007396698</pose>
          <mass>4.4655875421415463e-07</mass>
          <inertia>
            <ixx>1.5702411931223152e-10</ixx>
            <ixy>0.0</ixy>
            <ixz>0.0</ixz>
            <iyy>1.2506408298547429e-09</iyy>
            <iyz>0.0</iyz>
            <izz>1.2412368209400426e-09</izz>
          </inertia>
        </inertial>
        <collision name="RHTarsus2_collision">
          <pose>9.536726963688125e-08 3.576280249717456e-08 -1.6689291726379452e-07 0.0 1.2207044619572116e-07 6.103527461220892e-09</pose>
          <geometry>
            <mesh>
              <uri>../meshes/stl/RHTarsus2.stl</uri>
              <scale>1000.0 1000.0 1000.0</scale>
            </mesh>
          </geometry>
        </collision>
        <visual name="RHTarsus2_visual">
          <pose>9.536726963688125e-08 3.576280249717456e-08 -1.6689291726379452e-07 0.0 1.2207044619572116e-07 6.103527461220892e-09</pose>
          <geometry>
            <mesh>
              <uri>../meshes/stl/RHTarsus2.stl</uri>
              <scale>1000.0 1000.0 1000.0</scale>
            </mesh>
          </geometry>
          <material/>
        </visual>
      </link>
      <link name="RHTarsus3">
        <pose>0.36941787600517273 0.1835244745016098 -1.4401493072509766 0.3114085793495178 0.34027427434921265 0.09924408793449402</pose>
        <inertial>
          <pose>-0.004046386107802391 -0.0008038881351239979 -0.04870617762207985 0.6902742385864258 1.546101689338684 0.26581665873527527</pose>
          <mass>1.7172138836448318e-07</mass>
          <inertia>
            <ixx>4.2237091882900114e-11</ixx>
            <ixy>0.0</ixy>
            <ixz>0.0</ixz>
            <iyy>1.6048166485841857e-10</iyy>
            <iyz>0.0</iyz>
            <izz>1.5635778124740535e-10</izz>
          </inertia>
        </inertial>
        <collision name="RHTarsus3_collision">
          <pose>-1.1920910480966995e-07 3.576280249717456e-08 -7.152555525635762e-08 0.0 7.324227624394553e-08 2.441410806852673e-08</pose>
          <geometry>
            <mesh>
              <uri>../meshes/stl/RHTarsus3.stl</uri>
              <scale>1000.0 1000.0 1000.0</scale>
            </mesh>
          </geometry>
        </collision>
        <visual name="RHTarsus3_visual">
          <pose>-1.1920910480966995e-07 3.576280249717456e-08 -7.152555525635762e-08 0.0 7.324227624394553e-08 2.441410806852673e-08</pose>
          <geometry>
            <mesh>
              <uri>../meshes/stl/RHTarsus3.stl</uri>
              <scale>1000.0 1000.0 1000.0</scale>
            </mesh>
          </geometry>
          <material/>
        </visual>
      </link>
      <link name="RHTarsus4">
        <pose>0.3354257345199585 0.21028928458690643 -1.5266454219818115 0.5843173265457153 0.9690040946006775 0.43372851610183716</pose>
        <inertial>
          <pose>0.0 4.7683752057992024e-08 -1.9073465296060022e-07 0.535148024559021 1.4966950416564941 0.3660147190093994</pose>
          <mass>1.144339255559854e-07</mass>
          <inertia>
            <ixx>2.4712783025980313e-11</ixx>
            <ixy>0.0</ixy>
            <ixz>0.0</ixz>
            <iyy>2.5023629870877434e-10</iyy>
            <iyz>0.0</iyz>
            <izz>2.4930022229194714e-10</izz>
          </inertia>
        </inertial>
        <collision name="RHTarsus4_collision">
          <pose>4.768369876728684e-08 7.15256263106312e-08 -1.1920916165308881e-07 0.0 4.88280917920747e-08 4.882818060991667e-08</pose>
          <geometry>
            <mesh>
              <uri>../meshes/stl/RHTarsus4.stl</uri>
              <scale>1000.0 1000.0 1000.0</scale>
            </mesh>
          </geometry>
        </collision>
        <visual name="RHTarsus4_visual">
          <pose>4.768369876728684e-08 7.15256263106312e-08 -1.1920916165308881e-07 0.0 4.88280917920747e-08 4.882818060991667e-08</pose>
          <geometry>
            <mesh>
              <uri>../meshes/stl/RHTarsus4.stl</uri>
              <scale>1000.0 1000.0 1000.0</scale>
            </mesh>
          </geometry>
          <material/>
        </visual>
      </link>
      <link name="RHTarsus5">
        <pose>0.2728624641895294 0.22559969127178192 -1.561646819114685 -1.058811902999878 1.9181243181228638 -1.158355474472046</pose>
        <inertial>
          <pose>-0.00022531453578267246 7.836826262064278e-05 -0.052586596459150314 -0.37450075149536133 1.6293138265609741 2.474618434906006</pose>
          <mass>1.5831640110915208e-07</mass>
          <inertia>
            <ixx>4.285424278510291e-11</ixx>
            <ixy>0.0</ixy>
            <ixz>0.0</ixz>
            <iyy>1.2754025060455437e-10</iyy>
            <iyz>0.0</iyz>
            <izz>1.3637204765574993e-10</izz>
          </inertia>
        </inertial>
        <collision name="RHTarsus5_collision">
          <pose>1.1622907436503738e-07 2.384188135806653e-08 -2.1457640286826063e-07 -9.155249891534822e-09 9.765609121359375e-08 -2.441408142317414e-08</pose>
          <geometry>
            <mesh>
              <uri>../meshes/stl/RHTarsus5.stl</uri>
              <scale>1000.0 1000.0 1000.0</scale>
            </mesh>
          </geometry>
        </collision>
        <visual name="RHTarsus5_visual">
          <pose>1.1622907436503738e-07 2.384188135806653e-08 -2.1457640286826063e-07 -9.155249891534822e-09 9.765609121359375e-08 -2.441408142317414e-08</pose>
          <geometry>
            <mesh>
              <uri>../meshes/stl/RHTarsus5.stl</uri>
              <scale>1000.0 1000.0 1000.0</scale>
            </mesh>
          </geometry>
          <material/>
        </visual>
      </link>
      <link name="RHTibia">
        <pose>-0.05739247798919678 0.025145575404167175 -0.4172177016735077 0.12112925946712494 -0.10742367058992386 -0.013050300069153309</pose>
        <inertial>
          <pose>0.027649132534861565 0.009652992710471153 -0.4177238345146179 -1.2930299043655396 -1.625244140625 0.01823435164988041</pose>
          <mass>4.280436376694625e-06</mass>
          <inertia>
            <ixx>4.541709599180008e-09</ixx>
            <ixy>0.0</ixy>
            <ixz>0.0</ixz>
            <iyy>1.3679720292999974e-07</iyy>
            <iyz>0.0</iyz>
            <izz>1.374941274586889e-07</izz>
          </inertia>
        </inertial>
        <visual name="RHTibia_visual">
          <pose>-1.7881362168736814e-08 -1.1920932685427488e-08 -2.8684731034900324e-08 1.2207025612553934e-08 -1.2207051369728106e-08 1.525882087349828e-09</pose>
          <geometry>
            <mesh>
              <uri>../meshes/stl/RHTibia.stl</uri>
              <scale>1000.0 1000.0 1000.0</scale>
            </mesh>
          </geometry>
          <material/>
        </visual>
      </link>
      <link name="RMCoxa">
        <pose>0.06799986213445663 -0.12490185350179672 0.6798478960990906 0.0 -0.0872664526104927 0.0</pose>
        <inertial>
          <pose>-0.002372884890064597 -0.0048933750949800014 -0.07868670672178268 -0.03994356095790863 -1.0169451236724854 1.663708209991455</pose>
          <mass>3.2959672355899836e-06</mass>
          <inertia>
            <ixx>7.745654884458414e-09</ixx>
            <ixy>0.0</ixy>
            <ixz>0.0</ixz>
            <iyy>1.6132986906270694e-08</iyy>
            <iyz>0.0</iyz>
            <izz>1.783521534288855e-08</izz>
          </inertia>
        </inertial>
        <visual name="RMCoxa_visual">
          <pose>-1.1920929132713809e-08 0.0 -1.6018748993928966e-08 0.0 2.4414063659605745e-08 0.0</pose>
          <geometry>
            <mesh>
              <uri>../meshes/stl/RMCoxa.stl</uri>
              <scale>1000.0 1000.0 1000.0</scale>
            </mesh>
          </geometry>
          <material/>
        </visual>
      </link>
      <link name="RMCoxa_roll">
        <pose>0.06799986213445663 -0.1249018982052803 0.6798478364944458 0.1300269514322281 -3.7252917195473856e-08 -1.629815216119823e-08</pose>
        <inertial>
          <pose>-2.384184938364342e-08 -4.7683723636282593e-08 -1.2815002037314116e-07 -0.0 -0.0 0.0</pose>
          <mass>0.0</mass>
          <inertia>
            <ixx>0.0</ixx>
            <ixy>0.0</ixy>
            <ixz>0.0</ixz>
            <iyy>0.0</iyy>
            <iyz>0.0</iyz>
            <izz>0.0</izz>
          </inertia>
        </inertial>
      </link>
      <link name="RMCoxa_yaw">
        <pose>0.06799986958503723 -0.12490183860063553 0.6798478364944458 0.13002698123455048 -9.313226634333205e-09 -4.6566133171666024e-09</pose>
        <inertial>
          <pose>-5.960464122267695e-09 -4.7683723636282593e-08 -2.9802322387695312e-08 -0.0 -0.0 0.0</pose>
          <mass>0.0</mass>
          <inertia>
            <ixx>0.0</ixx>
            <ixy>0.0</ixy>
            <ixz>0.0</ixz>
            <iyy>0.0</iyy>
            <iyz>0.0</iyz>
            <izz>0.0</izz>
          </inertia>
        </inertial>
      </link>
      <link name="RMFemur">
        <pose>0.06745994091033936 -0.10158945620059967 0.499904602766037 0.1300269365310669 -7.450585570722978e-08 -2.793969500203275e-08</pose>
        <inertial>
          <pose>0.023515472188591957 -0.0019084576051682234 -0.4051283895969391 0.789853572845459 -1.5605460405349731 1.9371626377105713</pose>
          <mass>8.230783761246786e-06</mass>
          <inertia>
            <ixx>1.3593734791370518e-08</ixx>
            <ixy>0.0</ixy>
            <ixz>0.0</ixz>
            <iyy>4.0986093205923305e-07</iyy>
            <iyz>0.0</iyz>
            <izz>4.1009287829669595e-07</izz>
          </inertia>
        </inertial>
        <visual name="RMFemur_visual">
          <pose>1.7881381708662047e-08 -1.1920930909070648e-08 -8.046630028957225e-08 -1.2207033606159712e-08 -1.8599807249941591e-09 -4.33039770708632e-10</pose>
          <geometry>
            <mesh>
              <uri>../meshes/stl/RMFemur.stl</uri>
              <scale>1000.0 1000.0 1000.0</scale>
            </mesh>
          </geometry>
          <material/>
        </visual>
      </link>
      <link name="RMFemur_roll">
        <pose>0.06745990365743637 -0.1015893965959549 0.4999043941497803 0.26100292801856995 0.08432511985301971 0.022492390125989914</pose>
        <inertial>
          <pose>-5.960459681375596e-09 1.7881397695873602e-08 -1.758338044055563e-07 -0.0 -0.0 0.0</pose>
          <mass>0.0</mass>
          <inertia>
            <ixx>0.0</ixx>
            <ixy>0.0</ixy>
            <ixz>0.0</ixz>
            <iyy>0.0</iyy>
            <iyz>0.0</iyz>
            <izz>0.0</izz>
          </inertia>
        </inertial>
      </link>
      <link name="RMTarsus1">
        <pose>-0.06011718511581421 0.2708151936531067 -0.8966749906539917 0.5170009732246399 -0.6945066452026367 -0.3612196743488312</pose>
        <inertial>
          <pose>-0.007306968793272972 -0.001195430988445878 -0.15358710289001465 0.7168737053871155 1.6387239694595337 0.3150213658809662</pose>
          <mass>6.662970856873481e-07</mass>
          <inertia>
            <ixx>2.184113366658788e-10</ixx>
            <ixy>0.0</ixy>
            <ixz>0.0</ixz>
            <iyy>4.794743987941953e-09</iyy>
            <iyz>0.0</iyz>
            <izz>4.8344932127334485e-09</izz>
          </inertia>
        </inertial>
        <collision name="RMTarsus1_collision">
          <pose>-9.536742595628311e-08 7.152558367806705e-08 -2.9802313950000325e-09 4.882810245021574e-08 -4.8828113108356774e-08 -2.4414067212319424e-08</pose>
          <geometry>
            <mesh>
              <uri>../meshes/stl/RMTarsus1.stl</uri>
              <scale>1000.0 1000.0 1000.0</scale>
            </mesh>
          </geometry>
        </collision>
        <visual name="RMTarsus1_visual">
          <pose>-9.536742595628311e-08 7.152558367806705e-08 -2.9802313950000325e-09 4.882810245021574e-08 -4.8828113108356774e-08 -2.4414067212319424e-08</pose>
          <geometry>
            <mesh>
              <uri>../meshes/stl/RMTarsus1.stl</uri>
              <scale>1000.0 1000.0 1000.0</scale>
            </mesh>
          </geometry>
          <material/>
        </visual>
      </link>
      <link name="RMTarsus2">
        <pose>0.1418619155883789 0.3472708463668823 -1.0901727676391602 0.5343126654624939 0.2402595579624176 0.10118456184864044</pose>
        <inertial>
          <pose>-0.0034489838872104883 0.00012638571206480265 -0.08352508395910263 0.675876796245575 1.545806646347046 -2.063875675201416</pose>
          <mass>2.9889542789081263e-07</mass>
          <inertia>
            <ixx>8.096294424119362e-11</ixx>
            <ixy>0.0</ixy>
            <ixz>0.0</ixz>
            <iyy>6.075330745860752e-10</iyy>
            <iyz>0.0</iyz>
            <izz>6.128898670163614e-10</izz>
          </inertia>
        </inertial>
        <collision name="RMTarsus2_collision">
          <pose>-4.768367389829109e-08 4.7683723636282593e-08 -1.430512668321171e-07 9.765631148184184e-08 4.88282090316261e-08 -1.2207043376122328e-08</pose>
          <geometry>
            <mesh>
              <uri>../meshes/stl/RMTarsus2.stl</uri>
              <scale>1000.0 1000.0 1000.0</scale>
            </mesh>
          </geometry>
        </collision>
        <visual name="RMTarsus2_visual">
          <pose>-4.768367389829109e-08 4.7683723636282593e-08 -1.430512668321171e-07 9.765631148184184e-08 4.88282090316261e-08 -1.2207043376122328e-08</pose>
          <geometry>
            <mesh>
              <uri>../meshes/stl/RMTarsus2.stl</uri>
              <scale>1000.0 1000.0 1000.0</scale>
            </mesh>
          </geometry>
          <material/>
        </visual>
      </link>
      <link name="RMTarsus3">
        <pose>0.10103130340576172 0.42518848180770874 -1.224002718925476 1.2769254446029663 0.9849627614021301 1.0397244691848755</pose>
        <inertial>
          <pose>-0.0016742006409913301 -0.0024910455103963614 -0.04785547032952309 1.614872932434082 -1.6708186864852905 0.26087382435798645</pose>
          <mass>1.4935990140910388e-07</mass>
          <inertia>
            <ixx>3.5520843976979454e-11</ixx>
            <ixy>0.0</ixy>
            <ixz>0.0</ixz>
            <iyy>1.1751898347826705e-10</iyy>
            <iyz>0.0</iyz>
            <izz>1.2025686687844078e-10</izz>
          </inertia>
        </inertial>
        <collision name="RMTarsus3_collision">
          <pose>-7.152564052148591e-08 -2.3841861818141297e-08 -3.2782537573439186e-07 3.051756181093879e-08 2.4414028132468957e-08 0.0</pose>
          <geometry>
            <mesh>
              <uri>../meshes/stl/RMTarsus3.stl</uri>
              <scale>1000.0 1000.0 1000.0</scale>
            </mesh>
          </geometry>
        </collision>
        <visual name="RMTarsus3_visual">
          <pose>-7.152564052148591e-08 -2.3841861818141297e-08 -3.2782537573439186e-07 3.051756181093879e-08 2.4414028132468957e-08 0.0</pose>
          <geometry>
            <mesh>
              <uri>../meshes/stl/RMTarsus3.stl</uri>
              <scale>1000.0 1000.0 1000.0</scale>
            </mesh>
          </geometry>
          <material/>
        </visual>
      </link>
      <link name="RMTarsus4">
        <pose>0.013342678546905518 0.4507046639919281 -1.2382923364639282 -0.5739695429801941 2.5461456775665283 -0.6367456912994385</pose>
        <inertial>
          <pose>-2.1457685761561152e-07 1.1920928244535389e-07 -2.6822095833267667e-07 -1.0286282300949097 -1.670434832572937 0.31581422686576843</pose>
          <mass>8.690410754701314e-08</mass>
          <inertia>
            <ixx>1.819942193157816e-11</ixx>
            <ixy>0.0</ixy>
            <ixz>0.0</ixz>
            <iyy>1.2570442404316612e-10</iyy>
            <iyz>0.0</iyz>
            <izz>1.271910925977561e-10</izz>
          </inertia>
        </inertial>
        <collision name="RMTarsus4_collision">
          <pose>-2.1457685761561152e-07 1.1920928244535389e-07 -2.6822095833267667e-07 7.324221229509931e-08 4.8828109555643096e-08 0.0</pose>
          <geometry>
            <mesh>
              <uri>../meshes/stl/RMTarsus4.stl</uri>
              <scale>1000.0 1000.0 1000.0</scale>
            </mesh>
          </geometry>
        </collision>
        <visual name="RMTarsus4_visual">
          <pose>-2.1457685761561152e-07 1.1920928244535389e-07 -2.6822095833267667e-07 7.324221229509931e-08 4.8828109555643096e-08 0.0</pose>
          <geometry>
            <mesh>
              <uri>../meshes/stl/RMTarsus4.stl</uri>
              <scale>1000.0 1000.0 1000.0</scale>
            </mesh>
          </geometry>
          <material/>
        </visual>
      </link>
      <link name="RMTarsus5">
        <pose>-0.03246976435184479 0.4413987398147583 -1.1949589252471924 -0.35905733704566956 -2.8248214721679688 -0.13660211861133575</pose>
        <inertial>
          <pose>-0.0027946883346885443 0.0007006167434155941 -0.04338719695806503 -1.5421364307403564 -1.6818692684173584 -0.031598079949617386</pose>
          <mass>1.4474199837663808e-07</mass>
          <inertia>
            <ixx>3.3995331654332356e-11</ixx>
            <ixy>0.0</ixy>
            <ixz>0.0</ixz>
            <iyy>1.1711347585604174e-10</iyy>
            <iyz>0.0</iyz>
            <izz>1.2255173851220061e-10</izz>
          </inertia>
        </inertial>
        <collision name="RMTarsus5_collision">
          <pose>-7.748602115498215e-08 -7.152556236178498e-08 0.0 0.0 -2.4414099186742533e-08 -2.4414063659605745e-08</pose>
          <geometry>
            <mesh>
              <uri>../meshes/stl/RMTarsus5.stl</uri>
              <scale>1000.0 1000.0 1000.0</scale>
            </mesh>
          </geometry>
        </collision>
        <visual name="RMTarsus5_visual">
          <pose>-7.748602115498215e-08 -7.152556236178498e-08 0.0 0.0 -2.4414099186742533e-08 -2.4414063659605745e-08</pose>
          <geometry>
            <mesh>
              <uri>../meshes/stl/RMTarsus5.stl</uri>
              <scale>1000.0 1000.0 1000.0</scale>
            </mesh>
          </geometry>
          <material/>
        </visual>
      </link>
      <link name="RMTibia">
        <pose>-0.001809149980545044 0.0990733951330185 -0.2544671893119812 0.26100292801856995 0.08432509750127792 0.022492382675409317</pose>
        <inertial>
          <pose>0.021849842742085457 -0.0031391149386763573 -0.37384188175201416 1.210585594177246 1.5122177600860596 -0.2769756019115448</pose>
          <mass>3.631542526554793e-06</mass>
          <inertia>
            <ixx>2.9065389516331935e-09</ixx>
            <ixy>0.0</ixy>
            <ixz>0.0</ixz>
            <iyy>1.3520771526399404e-07</iyy>
            <iyz>0.0</iyz>
            <izz>1.3434653889263969e-07</izz>
          </inertia>
        </inertial>
        <visual name="RMTibia_visual">
          <pose>-1.5087408655745094e-08 0.0 -8.94070240065048e-09 0.0 -6.103526128953263e-09 0.0</pose>
          <geometry>
            <mesh>
              <uri>../meshes/stl/RMTibia.stl</uri>
              <scale>1000.0 1000.0 1000.0</scale>
            </mesh>
          </geometry>
          <material/>
        </visual>
      </link>
      <link name="Rostrum">
        <pose>0.8698111772537231 0.0006795641966164112 0.929617166519165 -0.0 1.570796012878418 0.0</pose>
        <inertial>
          <pose>-0.0003002314770128578 -0.00022978642664384097 -0.18048612773418427 -1.5745294094085693 -0.3231346309185028 -0.009324337355792522</pose>
          <mass>1.5627661807211787e-05</mass>
          <inertia>
            <ixx>2.1554352843929984e-07</ixx>
            <ixy>0.0</ixy>
            <ixz>0.0</ixz>
            <iyy>2.1028257933557665e-07</iyy>
            <iyz>0.0</iyz>
            <izz>2.4626195857237737e-07</izz>
          </inertia>
        </inertial>
        <visual name="Rostrum_visual">
          <pose>2.687855804595074e-08 4.6566129424663316e-11 9.536746858884726e-08 0.0 7.1525807499028815e-09 0.0</pose>
          <geometry>
            <mesh>
              <uri>../meshes/stl/Rostrum.stl</uri>
              <scale>1000.0 1000.0 1000.0</scale>
            </mesh>
          </geometry>
          <material/>
        </visual>
      </link>
      <link name="RWing">
        <pose>-0.0916057601571083 -0.36983364820480347 1.324182391166687 -1.1233777286179247e-07 0.5934117436408997 -1.5707966089248657</pose>
        <inertial>
          <pose>-0.11114867776632309 -1.077573537826538 0.08286423236131668 -0.033851005136966705 -0.052043452858924866 -1.6803632974624634</pose>
          <mass>2.4999207585520077e-06</mass>
          <inertia>
            <ixx>1.7107206267245927e-07</ixx>
            <ixy>0.0</ixy>
            <ixz>0.0</ixz>
            <iyy>8.044861135087566e-07</iyy>
            <iyz>0.0</iyz>
            <izz>9.66201523529629e-07</izz>
          </inertia>
        </inertial>
        <visual name="RWing_visual">
          <pose>1.4305119577784353e-07 1.7881394143159923e-08 -2.3841867147211815e-08 6.192395041182408e-09 -4.882813087192517e-08 -5.8207646737524e-15</pose>
          <geometry>
            <mesh>
              <uri>../meshes/stl/RWing.stl</uri>
              <scale>1000.0 1000.0 1000.0</scale>
            </mesh>
          </geometry>
          <material/>
        </visual>
      </link>
      <link name="RWing_roll">
        <pose>-0.09160572290420532 -0.36983367800712585 1.3241816759109497 0.0 -0.0 1.570796251296997</pose>
        <inertial>
          <pose>-4.7683716530855236e-08 5.9604645663569045e-09 9.536743306171047e-08 -0.0 -0.0 0.0</pose>
          <mass>0.0</mass>
          <inertia>
            <ixx>0.0</ixx>
            <ixy>0.0</ixy>
            <ixz>0.0</ixz>
            <iyy>0.0</iyy>
            <iyz>0.0</iyz>
            <izz>0.0</izz>
          </inertia>
        </inertial>
      </link>
      <link name="RWing_yaw">
        <pose>-0.09160572290420532 -0.36983364820480347 1.3241820335388184 -0.2967059314250946 -5.6331671771658876e-08 3.141592502593994</pose>
        <inertial>
          <pose>3.5762788286319847e-08 -2.3841863594498136e-08 3.2186517273657955e-07 -0.0 -0.0 0.0</pose>
          <mass>0.0</mass>
          <inertia>
            <ixx>0.0</ixx>
            <ixy>0.0</ixy>
            <ixz>0.0</ixz>
            <iyy>0.0</iyy>
            <iyz>0.0</iyz>
            <izz>0.0</izz>
          </inertia>
        </inertial>
      </link>
      <link name="Thorax">
        <pose>0.480766624212265 -5.75045135065011e-07 1.210771083831787 0.0 -0.0 0.0</pose>
        <inertial>
          <pose>-0.4311848282814026 -0.0003534229181241244 -0.06135521084070206 -1.5707879066467285 1.0229014158248901 -0.00014716469740960747</pose>
          <mass>0.000307167823005631</mass>
          <inertia>
            <ixx>2.4613874542105413e-05</ixx>
            <ixy>0.0</ixy>
            <ixz>0.0</ixz>
            <iyy>3.0137904141569884e-05</iyy>
            <iyz>0.0</iyz>
            <izz>3.3358713079231664e-05</izz>
          </inertia>
        </inertial>
        <visual name="Thorax_visual">
          <pose>-1.4305115314527939e-07 0.0 0.0 0.0 -0.0 0.0</pose>
          <geometry>
            <mesh>
              <uri>../meshes/stl/Thorax.stl</uri>
              <scale>1000.0 1000.0 1000.0</scale>
            </mesh>
          </geometry>
          <material/>
        </visual>
      </link>
      <link name="world">
        <pose>0.0 0.0 0.0 0.0 -0.0 0.0</pose>
        <inertial>
          <pose>0.0 0.0 0.0 -0.0 -0.0 0.0</pose>
          <mass>0.0</mass>
          <inertia>
            <ixx>0.0</ixx>
            <ixy>0.0</ixy>
            <ixz>0.0</ixz>
            <iyy>0.0</iyy>
            <iyz>0.0</iyz>
            <izz>0.0</izz>
          </inertia>
        </inertial>
      </link>
      <joint name="joint_A1A2" type="fixed">
        <parent>Thorax</parent>
        <child>A1A2</child>
        <pose>0.0 0.0 0.0 0.0 0.0 0.0</pose>
        <axis>
          <xyz>0.0 1.0 0.0</xyz>
          <limit>
            <lower>-3.1415927410125732</lower>
            <upper>3.1415927410125732</upper>
            <effort>10000000000.0</effort>
            <velocity>628.3185307179587</velocity>
          </limit>
        </axis>
      </joint>
      <joint name="joint_A3" type="fixed">
        <parent>A1A2</parent>
        <child>A3</child>
        <pose>0.0 0.0 0.0 0.0 0.0 0.0</pose>
        <axis>
          <xyz>0.0 1.0 0.0</xyz>
          <limit>
            <lower>-3.1415927410125732</lower>
            <upper>3.1415927410125732</upper>
            <effort>10000000000.0</effort>
            <velocity>628.3185307179587</velocity>
          </limit>
        </axis>
      </joint>
      <joint name="joint_A4" type="fixed">
        <parent>A3</parent>
        <child>A4</child>
        <pose>0.0 0.0 0.0 0.0 0.0 0.0</pose>
        <axis>
          <xyz>0.0 1.0 0.0</xyz>
          <limit>
            <lower>-3.1415927410125732</lower>
            <upper>3.1415927410125732</upper>
            <effort>10000000000.0</effort>
            <velocity>628.3185307179587</velocity>
          </limit>
        </axis>
      </joint>
      <joint name="joint_A5" type="fixed">
        <parent>A4</parent>
        <child>A5</child>
        <pose>0.0 0.0 0.0 0.0 0.0 0.0</pose>
        <axis>
          <xyz>0.0 1.0 0.0</xyz>
          <limit>
            <lower>-3.1415927410125732</lower>
            <upper>3.1415927410125732</upper>
            <effort>10000000000.0</effort>
            <velocity>628.3185307179587</velocity>
          </limit>
        </axis>
      </joint>
      <joint name="joint_A6" type="fixed">
        <parent>A5</parent>
        <child>A6</child>
        <pose>0.0 0.0 0.0 0.0 0.0 0.0</pose>
        <axis>
          <xyz>0.0 1.0 0.0</xyz>
          <limit>
            <lower>-3.1415927410125732</lower>
            <upper>3.1415927410125732</upper>
            <effort>10000000000.0</effort>
            <velocity>628.3185307179587</velocity>
          </limit>
        </axis>
      </joint>
      <joint name="joint_Haustellum" type="fixed">
        <parent>Rostrum</parent>
        <child>Haustellum</child>
        <pose>0.0 0.0 0.0 0.0 0.0 0.0</pose>
        <axis>
          <xyz>0.0 1.0 0.0</xyz>
          <limit>
            <lower>-3.1415912429844184</lower>
            <upper>3.1415912429844184</upper>
            <effort>10000000000.0</effort>
            <velocity>628.3185307179587</velocity>
          </limit>
        </axis>
      </joint>
      <joint name="joint_Head" type="fixed">
        <parent>Head_yaw</parent>
        <child>Head</child>
        <pose>0.0 0.0 0.0 0.0 0.0 0.0</pose>
        <axis>
          <xyz>0.0 1.0 0.0</xyz>
          <limit>
            <lower>-3.159385204943339</lower>
            <upper>3.159385204943339</upper>
            <effort>10000000000.0</effort>
            <velocity>628.3185307179587</velocity>
          </limit>
        </axis>
      </joint>
      <joint name="joint_Head_roll" type="fixed">
        <parent>Thorax</parent>
        <child>Head_roll</child>
        <pose>0.0 0.0 0.0 0.0 0.0 0.0</pose>
        <axis>
          <xyz>0.0 0.0 1.0</xyz>
          <limit>
            <lower>-1.8373615307932187</lower>
            <upper>1.8373615307932187</upper>
            <effort>10000000000.0</effort>
            <velocity>628.3185307179587</velocity>
          </limit>
        </axis>
      </joint>
      <joint name="joint_Head_yaw" type="fixed">
        <parent>Head_roll</parent>
        <child>Head_yaw</child>
        <pose>0.0 0.0 0.0 0.0 0.0 0.0</pose>
        <axis>
          <xyz>-1.0 -0.0 -0.0</xyz>
          <limit>
            <lower>-4.031278066820278</lower>
            <upper>4.031278066820278</upper>
            <effort>10000000000.0</effort>
            <velocity>628.3185307179587</velocity>
          </limit>
        </axis>
      </joint>
      <joint name="joint_LAntenna" type="fixed">
        <parent>Head</parent>
        <child>LAntenna</child>
        <pose>0.0 0.0 0.0 0.0 0.0 0.0</pose>
        <axis>
          <xyz>1.0 0.0 0.0</xyz>
          <limit>
            <lower>-2.9769279711748746</lower>
            <upper>2.9769279711748746</upper>
            <effort>10000000000.0</effort>
            <velocity>628.3185307179587</velocity>
          </limit>
        </axis>
      </joint>
      <joint name="joint_LEye" type="fixed">
        <parent>Head</parent>
        <child>LEye</child>
        <pose>0.0 0.0 0.0 0.0 0.0 0.0</pose>
        <axis>
          <xyz>1.0 0.0 0.0</xyz>
          <limit>
            <lower>0.0</lower>
            <upper>0.0</upper>
            <effort>10000000000.0</effort>
            <velocity>628.3185307179587</velocity>
          </limit>
        </axis>
      </joint>
      <joint name="joint_LFCoxa" type="continuous">
        <parent>LFCoxa_yaw</parent>
        <child>LFCoxa</child>
        <pose>0.0 0.0 0.0 0.0 0.0 0.0</pose>
        <axis>
          <xyz>0.0 1.0 0.0</xyz>
          <limit>
            <lower>-0.3230026538529655</lower>
            <upper>0.5548562980669347</upper>
            <effort>10000000000.0</effort>
            <velocity>628.3185307179587</velocity>
          </limit>
        </axis>
      </joint>
      <joint name="joint_LFCoxa_roll" type="fixed">
        <parent>Thorax</parent>
        <child>LFCoxa_roll</child>
        <pose>0.0 0.0 0.0 0.0 0.0 0.0</pose>
        <axis>
          <xyz>0.0 0.0 1.0</xyz>
          <limit>
            <lower>-3.1422325363661354</lower>
            <upper>3.1422325363661354</upper>
            <effort>10000000000.0</effort>
            <velocity>628.3185307179587</velocity>
          </limit>
        </axis>
      </joint>
      <joint name="joint_LFCoxa_yaw" type="fixed">
        <parent>LFCoxa_roll</parent>
        <child>LFCoxa_yaw</child>
        <pose>0.0 0.0 0.0 0.0 0.0 0.0</pose>
        <axis>
          <xyz>-1.0 -0.0 -0.0</xyz>
          <limit>
            <lower>-3.1415923665055345</lower>
            <upper>3.1415923665055345</upper>
            <effort>10000000000.0</effort>
            <velocity>628.3185307179587</velocity>
          </limit>
        </axis>
      </joint>
      <joint name="joint_LFFemur" type="continuous">
        <parent>LFCoxa</parent>
        <child>LFFemur</child>
        <pose>0.0 0.0 0.0 0.0 0.0 0.0</pose>
        <axis>
          <xyz>0.0 1.0 0.0</xyz>
          <limit>
            <lower>-2.7070260597076814</lower>
            <upper>-1.1927677266616241</upper>
            <effort>10000000000.0</effort>
            <velocity>628.3185307179587</velocity>
          </limit>
        </axis>
      </joint>
      <joint name="joint_LFFemur_roll" type="fixed">
        <parent>LFFemur</parent>
        <child>LFFemur_roll</child>
        <pose>0.0 0.0 0.0 0.0 0.0 0.0</pose>
        <axis>
          <xyz>0.0 0.0 1.0</xyz>
          <limit>
            <lower>-3.1415927410125732</lower>
            <upper>3.1415927410125732</upper>
            <effort>10000000000.0</effort>
            <velocity>628.3185307179587</velocity>
          </limit>
        </axis>
      </joint>
      <joint name="joint_LFTarsus1" type="fixed">
        <parent>LFTibia</parent>
        <child>LFTarsus1</child>
        <pose>0.0 0.0 0.0 0.0 0.0 0.0</pose>
        <axis>
          <xyz>0.0 1.0 0.0</xyz>
          <limit>
            <lower>-3.1415927410125732</lower>
            <upper>3.1415927410125732</upper>
            <effort>10000000000.0</effort>
            <velocity>628.3185307179587</velocity>
          </limit>
        </axis>
      </joint>
      <joint name="joint_LFTarsus2" type="fixed">
        <parent>LFTarsus1</parent>
        <child>LFTarsus2</child>
        <pose>0.0 0.0 0.0 0.0 0.0 0.0</pose>
        <axis>
          <xyz>0.0 1.0 0.0</xyz>
          <limit>
            <lower>-3.1415927410125732</lower>
            <upper>3.1415927410125732</upper>
            <effort>10000000000.0</effort>
            <velocity>628.3185307179587</velocity>
          </limit>
        </axis>
      </joint>
      <joint name="joint_LFTarsus3" type="fixed">
        <parent>LFTarsus2</parent>
        <child>LFTarsus3</child>
        <pose>0.0 0.0 0.0 0.0 0.0 0.0</pose>
        <axis>
          <xyz>0.0 1.0 0.0</xyz>
          <limit>
            <lower>-3.1415927410125732</lower>
            <upper>3.1415927410125732</upper>
            <effort>10000000000.0</effort>
            <velocity>628.3185307179587</velocity>
          </limit>
        </axis>
      </joint>
      <joint name="joint_LFTarsus4" type="fixed">
        <parent>LFTarsus3</parent>
        <child>LFTarsus4</child>
        <pose>0.0 0.0 0.0 0.0 0.0 0.0</pose>
        <axis>
          <xyz>0.0 1.0 0.0</xyz>
          <limit>
            <lower>-3.1415927410125732</lower>
            <upper>3.1415927410125732</upper>
            <effort>10000000000.0</effort>
            <velocity>628.3185307179587</velocity>
          </limit>
        </axis>
      </joint>
      <joint name="joint_LFTarsus5" type="fixed">
        <parent>LFTarsus4</parent>
        <child>LFTarsus5</child>
        <pose>0.0 0.0 0.0 0.0 0.0 0.0</pose>
        <axis>
          <xyz>0.0 1.0 0.0</xyz>
          <limit>
            <lower>-3.1415927410125732</lower>
            <upper>3.1415927410125732</upper>
            <effort>10000000000.0</effort>
            <velocity>628.3185307179587</velocity>
          </limit>
        </axis>
      </joint>
      <joint name="joint_LFTibia" type="continuous">
        <parent>LFFemur_roll</parent>
        <child>LFTibia</child>
        <pose>0.0 0.0 0.0 0.0 0.0 0.0</pose>
        <axis>
          <xyz>0.0 1.0 0.0</xyz>
          <limit>
            <lower>0.7795120577106078</lower>
            <upper>2.5142727572427592</upper>
            <effort>10000000000.0</effort>
            <velocity>628.3185307179587</velocity>
          </limit>
        </axis>
      </joint>
      <joint name="joint_LHaltere" type="fixed">
        <parent>LHaltere_yaw</parent>
        <child>LHaltere</child>
        <pose>0.0 0.0 0.0 0.0 0.0 0.0</pose>
        <axis>
          <xyz>0.0 1.0 0.0</xyz>
          <limit>
            <lower>-3.1447326076594218</lower>
            <upper>3.1447326076594218</upper>
            <effort>10000000000.0</effort>
            <velocity>628.3185307179587</velocity>
          </limit>
        </axis>
      </joint>
      <joint name="joint_LHaltere_roll" type="fixed">
        <parent>Thorax</parent>
        <child>LHaltere_roll</child>
        <pose>0.0 0.0 0.0 0.0 0.0 0.0</pose>
        <axis>
          <xyz>0.0 0.0 1.0</xyz>
          <limit>
            <lower>-3.1415927410125732</lower>
            <upper>3.1415927410125732</upper>
            <effort>10000000000.0</effort>
            <velocity>628.3185307179587</velocity>
          </limit>
        </axis>
      </joint>
      <joint name="joint_LHaltere_yaw" type="fixed">
        <parent>LHaltere_roll</parent>
        <child>LHaltere_yaw</child>
        <pose>0.0 0.0 0.0 0.0 0.0 0.0</pose>
        <axis>
          <xyz>-1.0 -0.0 -0.0</xyz>
          <limit>
            <lower>-3.138449878309415</lower>
            <upper>3.138449878309415</upper>
            <effort>10000000000.0</effort>
            <velocity>628.3185307179587</velocity>
          </limit>
        </axis>
      </joint>
      <joint name="joint_LHCoxa" type="fixed">
        <parent>Thorax</parent>
        <child>LHCoxa</child>
        <pose>0.0 0.0 0.0 0.0 0.0 0.0</pose>
        <axis>
          <xyz>0.0 1.0 0.0</xyz>
          <limit>
            <lower>-3.1346657110746308</lower>
            <upper>3.1346657110746308</upper>
            <effort>10000000000.0</effort>
            <velocity>628.3185307179587</velocity>
          </limit>
        </axis>
      </joint>
      <joint name="joint_LHCoxa_roll" type="continuous">
        <parent>LHCoxa_yaw</parent>
        <child>LHCoxa_roll</child>
        <pose>0.0 0.0 0.0 0.0 0.0 0.0</pose>
        <axis>
          <xyz>0.0 0.0 1.0</xyz>
          <limit>
            <lower>2.328081579351015</lower>
            <upper>2.8665233073854983</upper>
            <effort>10000000000.0</effort>
            <velocity>628.3185307179587</velocity>
          </limit>
        </axis>
      </joint>
      <joint name="joint_LHCoxa_yaw" type="fixed">
        <parent>LHCoxa</parent>
        <child>LHCoxa_yaw</child>
        <pose>0.0 0.0 0.0 0.0 0.0 0.0</pose>
        <axis>
          <xyz>-1.0 -0.0 -0.0</xyz>
          <limit>
            <lower>-3.1510057496754693</lower>
            <upper>3.1510057496754693</upper>
            <effort>10000000000.0</effort>
            <velocity>628.3185307179587</velocity>
          </limit>
        </axis>
      </joint>
      <joint name="joint_LHFemur" type="continuous">
        <parent>LHCoxa_roll</parent>
        <child>LHFemur</child>
        <pose>0.0 0.0 0.0 0.0 0.0 0.0</pose>
        <axis>
          <xyz>0.0 1.0 0.0</xyz>
          <limit>
            <lower>-2.4822204407825286</lower>
            <upper>-1.1429577335102055</upper>
            <effort>10000000000.0</effort>
            <velocity>628.3185307179587</velocity>
          </limit>
        </axis>
      </joint>
      <joint name="joint_LHFemur_roll" type="fixed">
        <parent>LHFemur</parent>
        <child>LHFemur_roll</child>
        <pose>0.0 0.0 0.0 0.0 0.0 0.0</pose>
        <axis>
          <xyz>0.0 0.0 1.0</xyz>
          <limit>
            <lower>-3.1415927410125732</lower>
            <upper>3.1415927410125732</upper>
            <effort>10000000000.0</effort>
            <velocity>628.3185307179587</velocity>
          </limit>
        </axis>
      </joint>
      <joint name="joint_LHTarsus1" type="fixed">
        <parent>LHTibia</parent>
        <child>LHTarsus1</child>
        <pose>0.0 0.0 0.0 0.0 0.0 0.0</pose>
        <axis>
          <xyz>0.0 1.0 0.0</xyz>
          <limit>
            <lower>-3.1415813185581385</lower>
            <upper>3.1415813185581385</upper>
            <effort>10000000000.0</effort>
            <velocity>628.3185307179587</velocity>
          </limit>
        </axis>
      </joint>
      <joint name="joint_LHTarsus2" type="fixed">
        <parent>LHTarsus1</parent>
        <child>LHTarsus2</child>
        <pose>0.0 0.0 0.0 0.0 0.0 0.0</pose>
        <axis>
          <xyz>0.0 1.0 0.0</xyz>
          <limit>
            <lower>-3.141493684665977</lower>
            <upper>3.141493684665977</upper>
            <effort>10000000000.0</effort>
            <velocity>628.3185307179587</velocity>
          </limit>
        </axis>
      </joint>
      <joint name="joint_LHTarsus3" type="fixed">
        <parent>LHTarsus2</parent>
        <child>LHTarsus3</child>
        <pose>0.0 0.0 0.0 0.0 0.0 0.0</pose>
        <axis>
          <xyz>0.0 1.0 0.0</xyz>
          <limit>
            <lower>-3.141284903764955</lower>
            <upper>3.141284903764955</upper>
            <effort>10000000000.0</effort>
            <velocity>628.3185307179587</velocity>
          </limit>
        </axis>
      </joint>
      <joint name="joint_LHTarsus4" type="fixed">
        <parent>LHTarsus3</parent>
        <child>LHTarsus4</child>
        <pose>0.0 0.0 0.0 0.0 0.0 0.0</pose>
        <axis>
          <xyz>0.0 1.0 0.0</xyz>
          <limit>
            <lower>-3.1415625932679463</lower>
            <upper>3.1415625932679463</upper>
            <effort>10000000000.0</effort>
            <velocity>628.3185307179587</velocity>
          </limit>
        </axis>
      </joint>
      <joint name="joint_LHTarsus5" type="fixed">
        <parent>LHTarsus4</parent>
        <child>LHTarsus5</child>
        <pose>0.0 0.0 0.0 0.0 0.0 0.0</pose>
        <axis>
          <xyz>0.0 1.0 0.0</xyz>
          <limit>
            <lower>-3.1415889959432577</lower>
            <upper>3.1415889959432577</upper>
            <effort>10000000000.0</effort>
            <velocity>628.3185307179587</velocity>
          </limit>
        </axis>
      </joint>
      <joint name="joint_LHTibia" type="continuous">
        <parent>LHFemur_roll</parent>
        <child>LHTibia</child>
        <pose>0.0 0.0 0.0 0.0 0.0 0.0</pose>
        <axis>
          <xyz>0.0 1.0 0.0</xyz>
          <limit>
            <lower>0.6137228182602668</lower>
            <upper>2.6959491072995783</upper>
            <effort>10000000000.0</effort>
            <velocity>628.3185307179587</velocity>
          </limit>
        </axis>
      </joint>
      <joint name="joint_LMCoxa" type="fixed">
        <parent>Thorax</parent>
        <child>LMCoxa</child>
        <pose>0.0 0.0 0.0 0.0 0.0 0.0</pose>
        <axis>
          <xyz>0.0 1.0 0.0</xyz>
          <limit>
            <lower>-3.1472331036320957</lower>
            <upper>3.1472331036320957</upper>
            <effort>10000000000.0</effort>
            <velocity>628.3185307179587</velocity>
          </limit>
        </axis>
      </joint>
      <joint name="joint_LMCoxa_roll" type="continuous">
        <parent>LMCoxa_yaw</parent>
        <child>LMCoxa_roll</child>
        <pose>0.0 0.0 0.0 0.0 0.0 0.0</pose>
        <axis>
          <xyz>0.0 0.0 1.0</xyz>
          <limit>
            <lower>1.7633980792760797</lower>
            <upper>2.3208026592658286</upper>
            <effort>10000000000.0</effort>
            <velocity>628.3185307179587</velocity>
          </limit>
        </axis>
      </joint>
      <joint name="joint_LMCoxa_yaw" type="fixed">
        <parent>LMCoxa</parent>
        <child>LMCoxa_yaw</child>
        <pose>0.0 0.0 0.0 0.0 0.0 0.0</pose>
        <axis>
          <xyz>-1.0 -0.0 -0.0</xyz>
          <limit>
            <lower>-3.141587994648568</lower>
            <upper>3.141587994648568</upper>
            <effort>10000000000.0</effort>
            <velocity>628.3185307179587</velocity>
          </limit>
        </axis>
      </joint>
      <joint name="joint_LMFemur" type="continuous">
        <parent>LMCoxa_roll</parent>
        <child>LMFemur</child>
        <pose>0.0 0.0 0.0 0.0 0.0 0.0</pose>
        <axis>
          <xyz>0.0 1.0 0.0</xyz>
          <limit>
            <lower>-2.363638739290062</lower>
            <upper>-1.6424144373215874</upper>
            <effort>10000000000.0</effort>
            <velocity>628.3185307179587</velocity>
          </limit>
        </axis>
      </joint>
      <joint name="joint_LMFemur_roll" type="fixed">
        <parent>LMFemur</parent>
        <child>LMFemur_roll</child>
        <pose>0.0 0.0 0.0 0.0 0.0 0.0</pose>
        <axis>
          <xyz>0.0 0.0 1.0</xyz>
          <limit>
            <lower>-3.1384489420422645</lower>
            <upper>3.1384489420422645</upper>
            <effort>10000000000.0</effort>
            <velocity>628.3185307179587</velocity>
          </limit>
        </axis>
      </joint>
      <joint name="joint_LMTarsus1" type="fixed">
        <parent>LMTibia</parent>
        <child>LMTarsus1</child>
        <pose>0.0 0.0 0.0 0.0 0.0 0.0</pose>
        <axis>
          <xyz>0.0 1.0 0.0</xyz>
          <limit>
            <lower>-3.1415841273552365</lower>
            <upper>3.1415841273552365</upper>
            <effort>10000000000.0</effort>
            <velocity>628.3185307179587</velocity>
          </limit>
        </axis>
      </joint>
      <joint name="joint_LMTarsus2" type="fixed">
        <parent>LMTarsus1</parent>
        <child>LMTarsus2</child>
        <pose>0.0 0.0 0.0 0.0 0.0 0.0</pose>
        <axis>
          <xyz>0.0 1.0 0.0</xyz>
          <limit>
            <lower>-3.1415912429844184</lower>
            <upper>3.1415912429844184</upper>
            <effort>10000000000.0</effort>
            <velocity>628.3185307179587</velocity>
          </limit>
        </axis>
      </joint>
      <joint name="joint_LMTarsus3" type="fixed">
        <parent>LMTarsus2</parent>
        <child>LMTarsus3</child>
        <pose>0.0 0.0 0.0 0.0 0.0 0.0</pose>
        <axis>
          <xyz>0.0 1.0 0.0</xyz>
          <limit>
            <lower>-3.1415889959432577</lower>
            <upper>3.1415889959432577</upper>
            <effort>10000000000.0</effort>
            <velocity>628.3185307179587</velocity>
          </limit>
        </axis>
      </joint>
      <joint name="joint_LMTarsus4" type="fixed">
        <parent>LMTarsus3</parent>
        <child>LMTarsus4</child>
        <pose>0.0 0.0 0.0 0.0 0.0 0.0</pose>
        <axis>
          <xyz>0.0 1.0 0.0</xyz>
          <limit>
            <lower>-3.1415813185581385</lower>
            <upper>3.1415813185581385</upper>
            <effort>10000000000.0</effort>
            <velocity>628.3185307179587</velocity>
          </limit>
        </axis>
      </joint>
      <joint name="joint_LMTarsus5" type="fixed">
        <parent>LMTarsus4</parent>
        <child>LMTarsus5</child>
        <pose>0.0 0.0 0.0 0.0 0.0 0.0</pose>
        <axis>
          <xyz>0.0 1.0 0.0</xyz>
          <limit>
            <lower>-3.1414833859077995</lower>
            <upper>3.1414833859077995</upper>
            <effort>10000000000.0</effort>
            <velocity>628.3185307179587</velocity>
          </limit>
        </axis>
      </joint>
      <joint name="joint_LMTibia" type="continuous">
        <parent>LMFemur_roll</parent>
        <child>LMTibia</child>
        <pose>0.0 0.0 0.0 0.0 0.0 0.0</pose>
        <axis>
          <xyz>0.0 1.0 0.0</xyz>
          <limit>
            <lower>1.5742404712255267</lower>
            <upper>2.4686521684717793</upper>
            <effort>10000000000.0</effort>
            <velocity>628.3185307179587</velocity>
          </limit>
        </axis>
      </joint>
      <joint name="joint_LWing" type="fixed">
        <parent>LWing_yaw</parent>
        <child>LWing</child>
        <pose>0.0 0.0 0.0 0.0 0.0 0.0</pose>
        <axis>
          <xyz>0.0 1.0 0.0</xyz>
          <limit>
            <lower>-3.1415927410125732</lower>
            <upper>3.1415927410125732</upper>
            <effort>10000000000.0</effort>
            <velocity>628.3185307179587</velocity>
          </limit>
        </axis>
      </joint>
      <joint name="joint_LWing_roll" type="fixed">
        <parent>Thorax</parent>
        <child>LWing_roll</child>
        <pose>0.0 0.0 0.0 0.0 0.0 0.0</pose>
        <axis>
          <xyz>0.0 0.0 1.0</xyz>
          <limit>
            <lower>-3.1415927410125732</lower>
            <upper>3.1415927410125732</upper>
            <effort>10000000000.0</effort>
            <velocity>628.3185307179587</velocity>
          </limit>
        </axis>
      </joint>
      <joint name="joint_LWing_yaw" type="fixed">
        <parent>LWing_roll</parent>
        <child>LWing_yaw</child>
        <pose>0.0 0.0 0.0 0.0 0.0 0.0</pose>
        <axis>
          <xyz>-1.0 -0.0 -0.0</xyz>
          <limit>
            <lower>-3.1415927410125732</lower>
            <upper>3.1415927410125732</upper>
            <effort>10000000000.0</effort>
            <velocity>628.3185307179587</velocity>
          </limit>
        </axis>
      </joint>
      <joint name="joint_RAntenna" type="fixed">
        <parent>Head</parent>
        <child>RAntenna</child>
        <pose>0.0 0.0 0.0 0.0 0.0 0.0</pose>
        <axis>
          <xyz>1.0 0.0 0.0</xyz>
          <limit>
            <lower>-2.976923630144661</lower>
            <upper>2.976923630144661</upper>
            <effort>10000000000.0</effort>
            <velocity>628.3185307179587</velocity>
          </limit>
        </axis>
      </joint>
      <joint name="joint_REye" type="fixed">
        <parent>Head</parent>
        <child>REye</child>
        <pose>0.0 0.0 0.0 0.0 0.0 0.0</pose>
        <axis>
          <xyz>1.0 0.0 0.0</xyz>
          <limit>
            <lower>0.0</lower>
            <upper>0.0</upper>
            <effort>10000000000.0</effort>
            <velocity>628.3185307179587</velocity>
          </limit>
        </axis>
      </joint>
      <joint name="joint_RFCoxa" type="continuous">
        <parent>RFCoxa_yaw</parent>
        <child>RFCoxa</child>
        <pose>0.0 0.0 0.0 0.0 0.0 0.0</pose>
        <axis>
          <xyz>0.0 1.0 0.0</xyz>
          <limit>
            <lower>-0.3230026538529655</lower>
            <upper>0.5548562980669347</upper>
            <effort>10000000000.0</effort>
            <velocity>628.3185307179587</velocity>
          </limit>
        </axis>
      </joint>
      <joint name="joint_RFCoxa_roll" type="fixed">
        <parent>Thorax</parent>
        <child>RFCoxa_roll</child>
        <pose>0.0 0.0 0.0 0.0 0.0 0.0</pose>
        <axis>
          <xyz>-0.0 -0.0 -1.0</xyz>
          <limit>
            <lower>-3.1422325363661354</lower>
            <upper>3.1422325363661354</upper>
            <effort>10000000000.0</effort>
            <velocity>628.3185307179587</velocity>
          </limit>
        </axis>
      </joint>
      <joint name="joint_RFCoxa_yaw" type="fixed">
        <parent>RFCoxa_roll</parent>
        <child>RFCoxa_yaw</child>
        <pose>0.0 0.0 0.0 0.0 0.0 0.0</pose>
        <axis>
          <xyz>-1.0 -0.0 -0.0</xyz>
          <limit>
            <lower>-3.1415923665055345</lower>
            <upper>3.1415923665055345</upper>
            <effort>10000000000.0</effort>
            <velocity>628.3185307179587</velocity>
          </limit>
        </axis>
      </joint>
      <joint name="joint_RFFemur" type="continuous">
        <parent>RFCoxa</parent>
        <child>RFFemur</child>
        <pose>0.0 0.0 0.0 0.0 0.0 0.0</pose>
        <axis>
          <xyz>0.0 1.0 0.0</xyz>
          <limit>
            <lower>-2.7070260597076814</lower>
            <upper>-1.1927677266616241</upper>
            <effort>10000000000.0</effort>
            <velocity>628.3185307179587</velocity>
          </limit>
        </axis>
      </joint>
      <joint name="joint_RFFemur_roll" type="fixed">
        <parent>RFFemur</parent>
        <child>RFFemur_roll</child>
        <pose>0.0 0.0 0.0 0.0 0.0 0.0</pose>
        <axis>
          <xyz>-0.0 -0.0 -1.0</xyz>
          <limit>
            <lower>-3.1415927410125732</lower>
            <upper>3.1415927410125732</upper>
            <effort>10000000000.0</effort>
            <velocity>628.3185307179587</velocity>
          </limit>
        </axis>
      </joint>
      <joint name="joint_RFTarsus1" type="fixed">
        <parent>RFTibia</parent>
        <child>RFTarsus1</child>
        <pose>0.0 0.0 0.0 0.0 0.0 0.0</pose>
        <axis>
          <xyz>0.0 1.0 0.0</xyz>
          <limit>
            <lower>-3.1415927410125732</lower>
            <upper>3.1415927410125732</upper>
            <effort>10000000000.0</effort>
            <velocity>628.3185307179587</velocity>
          </limit>
        </axis>
      </joint>
      <joint name="joint_RFTarsus2" type="fixed">
        <parent>RFTarsus1</parent>
        <child>RFTarsus2</child>
        <pose>0.0 0.0 0.0 0.0 0.0 0.0</pose>
        <axis>
          <xyz>0.0 1.0 0.0</xyz>
          <limit>
            <lower>-3.1415927410125732</lower>
            <upper>3.1415927410125732</upper>
            <effort>10000000000.0</effort>
            <velocity>628.3185307179587</velocity>
          </limit>
        </axis>
      </joint>
      <joint name="joint_RFTarsus3" type="fixed">
        <parent>RFTarsus2</parent>
        <child>RFTarsus3</child>
        <pose>0.0 0.0 0.0 0.0 0.0 0.0</pose>
        <axis>
          <xyz>0.0 1.0 0.0</xyz>
          <limit>
            <lower>-3.1415927410125732</lower>
            <upper>3.1415927410125732</upper>
            <effort>10000000000.0</effort>
            <velocity>628.3185307179587</velocity>
          </limit>
        </axis>
      </joint>
      <joint name="joint_RFTarsus4" type="fixed">
        <parent>RFTarsus3</parent>
        <child>RFTarsus4</child>
        <pose>0.0 0.0 0.0 0.0 0.0 0.0</pose>
        <axis>
          <xyz>0.0 1.0 0.0</xyz>
          <limit>
            <lower>-3.1415927410125732</lower>
            <upper>3.1415927410125732</upper>
            <effort>10000000000.0</effort>
            <velocity>628.3185307179587</velocity>
          </limit>
        </axis>
      </joint>
      <joint name="joint_RFTarsus5" type="fixed">
        <parent>RFTarsus4</parent>
        <child>RFTarsus5</child>
        <pose>0.0 0.0 0.0 0.0 0.0 0.0</pose>
        <axis>
          <xyz>0.0 1.0 0.0</xyz>
          <limit>
            <lower>-3.1415927410125732</lower>
            <upper>3.1415927410125732</upper>
            <effort>10000000000.0</effort>
            <velocity>628.3185307179587</velocity>
          </limit>
        </axis>
      </joint>
      <joint name="joint_RFTibia" type="continuous">
        <parent>RFFemur_roll</parent>
        <child>RFTibia</child>
        <pose>0.0 0.0 0.0 0.0 0.0 0.0</pose>
        <axis>
          <xyz>0.0 1.0 0.0</xyz>
          <limit>
            <lower>0.7795120577106078</lower>
            <upper>2.5142727572427592</upper>
            <effort>10000000000.0</effort>
            <velocity>628.3185307179587</velocity>
          </limit>
        </axis>
      </joint>
      <joint name="joint_RHaltere" type="fixed">
        <parent>RHaltere_yaw</parent>
        <child>RHaltere</child>
        <pose>0.0 0.0 0.0 0.0 0.0 0.0</pose>
        <axis>
          <xyz>0.0 1.0 0.0</xyz>
          <limit>
            <lower>-3.1428684122978283</lower>
            <upper>3.1428684122978283</upper>
            <effort>10000000000.0</effort>
            <velocity>628.3185307179587</velocity>
          </limit>
        </axis>
      </joint>
      <joint name="joint_RHaltere_roll" type="fixed">
        <parent>Thorax</parent>
        <child>RHaltere_roll</child>
        <pose>0.0 0.0 0.0 0.0 0.0 0.0</pose>
        <axis>
          <xyz>-0.0 -0.0 -1.0</xyz>
          <limit>
            <lower>-3.1415927410125732</lower>
            <upper>3.1415927410125732</upper>
            <effort>10000000000.0</effort>
            <velocity>628.3185307179587</velocity>
          </limit>
        </axis>
      </joint>
      <joint name="joint_RHaltere_yaw" type="fixed">
        <parent>RHaltere_roll</parent>
        <child>RHaltere_yaw</child>
        <pose>0.0 0.0 0.0 0.0 0.0 0.0</pose>
        <axis>
          <xyz>-1.0 -0.0 -0.0</xyz>
          <limit>
            <lower>-3.138449878309415</lower>
            <upper>3.138449878309415</upper>
            <effort>10000000000.0</effort>
            <velocity>628.3185307179587</velocity>
          </limit>
        </axis>
      </joint>
      <joint name="joint_RHCoxa" type="fixed">
        <parent>Thorax</parent>
        <child>RHCoxa</child>
        <pose>0.0 0.0 0.0 0.0 0.0 0.0</pose>
        <axis>
          <xyz>0.0 1.0 0.0</xyz>
          <limit>
            <lower>-3.153507575982834</lower>
            <upper>3.153507575982834</upper>
            <effort>10000000000.0</effort>
            <velocity>628.3185307179587</velocity>
          </limit>
        </axis>
      </joint>
      <joint name="joint_RHCoxa_roll" type="continuous">
        <parent>RHCoxa_yaw</parent>
        <child>RHCoxa_roll</child>
        <pose>0.0 0.0 0.0 0.0 0.0 0.0</pose>
        <axis>
          <xyz>-0.0 -0.0 -1.0</xyz>
          <limit>
            <lower>2.328081579351015</lower>
            <upper>2.8665233073854983</upper>
            <effort>10000000000.0</effort>
            <velocity>628.3185307179587</velocity>
          </limit>
        </axis>
      </joint>
      <joint name="joint_RHCoxa_yaw" type="fixed">
        <parent>RHCoxa</parent>
        <child>RHCoxa_yaw</child>
        <pose>0.0 0.0 0.0 0.0 0.0 0.0</pose>
        <axis>
          <xyz>-1.0 -0.0 -0.0</xyz>
          <limit>
            <lower>-3.1510057496754693</lower>
            <upper>3.1510057496754693</upper>
            <effort>10000000000.0</effort>
            <velocity>628.3185307179587</velocity>
          </limit>
        </axis>
      </joint>
      <joint name="joint_RHFemur" type="continuous">
        <parent>RHCoxa_roll</parent>
        <child>RHFemur</child>
        <pose>0.0 0.0 0.0 0.0 0.0 0.0</pose>
        <axis>
          <xyz>0.0 1.0 0.0</xyz>
          <limit>
            <lower>-2.4822204407825286</lower>
            <upper>-1.1429577335102055</upper>
            <effort>10000000000.0</effort>
            <velocity>628.3185307179587</velocity>
          </limit>
        </axis>
      </joint>
      <joint name="joint_RHFemur_roll" type="fixed">
        <parent>RHFemur</parent>
        <child>RHFemur_roll</child>
        <pose>0.0 0.0 0.0 0.0 0.0 0.0</pose>
        <axis>
          <xyz>-0.0 -0.0 -1.0</xyz>
          <limit>
            <lower>-3.1415927410125732</lower>
            <upper>3.1415927410125732</upper>
            <effort>10000000000.0</effort>
            <velocity>628.3185307179587</velocity>
          </limit>
        </axis>
      </joint>
      <joint name="joint_RHTarsus1" type="fixed">
        <parent>RHTibia</parent>
        <child>RHTarsus1</child>
        <pose>0.0 0.0 0.0 0.0 0.0 0.0</pose>
        <axis>
          <xyz>0.0 1.0 0.0</xyz>
          <limit>
            <lower>-3.1415927410125732</lower>
            <upper>3.1415927410125732</upper>
            <effort>10000000000.0</effort>
            <velocity>628.3185307179587</velocity>
          </limit>
        </axis>
      </joint>
      <joint name="joint_RHTarsus2" type="fixed">
        <parent>RHTarsus1</parent>
        <child>RHTarsus2</child>
        <pose>0.0 0.0 0.0 0.0 0.0 0.0</pose>
        <axis>
          <xyz>0.0 1.0 0.0</xyz>
          <limit>
            <lower>-3.1415841273552365</lower>
            <upper>3.1415841273552365</upper>
            <effort>10000000000.0</effort>
            <velocity>628.3185307179587</velocity>
          </limit>
        </axis>
      </joint>
      <joint name="joint_RHTarsus3" type="fixed">
        <parent>RHTarsus2</parent>
        <child>RHTarsus3</child>
        <pose>0.0 0.0 0.0 0.0 0.0 0.0</pose>
        <axis>
          <xyz>0.0 1.0 0.0</xyz>
          <limit>
            <lower>-3.1415449915461044</lower>
            <upper>3.1415449915461044</upper>
            <effort>10000000000.0</effort>
            <velocity>628.3185307179587</velocity>
          </limit>
        </axis>
      </joint>
      <joint name="joint_RHTarsus4" type="fixed">
        <parent>RHTarsus3</parent>
        <child>RHTarsus4</child>
        <pose>0.0 0.0 0.0 0.0 0.0 0.0</pose>
        <axis>
          <xyz>0.0 1.0 0.0</xyz>
          <limit>
            <lower>-3.1415399357414633</lower>
            <upper>3.1415399357414633</upper>
            <effort>10000000000.0</effort>
            <velocity>628.3185307179587</velocity>
          </limit>
        </axis>
      </joint>
      <joint name="joint_RHTarsus5" type="fixed">
        <parent>RHTarsus4</parent>
        <child>RHTarsus5</child>
        <pose>0.0 0.0 0.0 0.0 0.0 0.0</pose>
        <axis>
          <xyz>0.0 1.0 0.0</xyz>
          <limit>
            <lower>-3.1415912429844184</lower>
            <upper>3.1415912429844184</upper>
            <effort>10000000000.0</effort>
            <velocity>628.3185307179587</velocity>
          </limit>
        </axis>
      </joint>
      <joint name="joint_RHTibia" type="continuous">
        <parent>RHFemur_roll</parent>
        <child>RHTibia</child>
        <pose>0.0 0.0 0.0 0.0 0.0 0.0</pose>
        <axis>
          <xyz>0.0 1.0 0.0</xyz>
          <limit>
            <lower>0.6137228182602668</lower>
            <upper>2.6959491072995783</upper>
            <effort>10000000000.0</effort>
            <velocity>628.3185307179587</velocity>
          </limit>
        </axis>
      </joint>
      <joint name="joint_RMCoxa" type="fixed">
        <parent>Thorax</parent>
        <child>RMCoxa</child>
        <pose>0.0 0.0 0.0 0.0 0.0 0.0</pose>
        <axis>
          <xyz>0.0 1.0 0.0</xyz>
          <limit>
            <lower>-3.134665087714937</lower>
            <upper>3.134665087714937</upper>
            <effort>10000000000.0</effort>
            <velocity>628.3185307179587</velocity>
          </limit>
        </axis>
      </joint>
      <joint name="joint_RMCoxa_roll" type="continuous">
        <parent>RMCoxa_yaw</parent>
        <child>RMCoxa_roll</child>
        <pose>0.0 0.0 0.0 0.0 0.0 0.0</pose>
        <axis>
          <xyz>-0.0 -0.0 -1.0</xyz>
          <limit>
            <lower>1.7633980792760797</lower>
            <upper>2.3208026592658286</upper>
            <effort>10000000000.0</effort>
            <velocity>628.3185307179587</velocity>
          </limit>
        </axis>
      </joint>
      <joint name="joint_RMCoxa_yaw" type="fixed">
        <parent>RMCoxa</parent>
        <child>RMCoxa_yaw</child>
        <pose>0.0 0.0 0.0 0.0 0.0 0.0</pose>
        <axis>
          <xyz>-1.0 -0.0 -0.0</xyz>
          <limit>
            <lower>-3.141587994648568</lower>
            <upper>3.141587994648568</upper>
            <effort>10000000000.0</effort>
            <velocity>628.3185307179587</velocity>
          </limit>
        </axis>
      </joint>
      <joint name="joint_RMFemur" type="continuous">
        <parent>RMCoxa_roll</parent>
        <child>RMFemur</child>
        <pose>0.0 0.0 0.0 0.0 0.0 0.0</pose>
        <axis>
          <xyz>0.0 1.0 0.0</xyz>
          <limit>
            <lower>-2.363638739290062</lower>
            <upper>-1.6424144373215874</upper>
            <effort>10000000000.0</effort>
            <velocity>628.3185307179587</velocity>
          </limit>
        </axis>
      </joint>
      <joint name="joint_RMFemur_roll" type="fixed">
        <parent>RMFemur</parent>
        <child>RMFemur_roll</child>
        <pose>0.0 0.0 0.0 0.0 0.0 0.0</pose>
        <axis>
          <xyz>-0.0 -0.0 -1.0</xyz>
          <limit>
            <lower>-3.1384489420422645</lower>
            <upper>3.1384489420422645</upper>
            <effort>10000000000.0</effort>
            <velocity>628.3185307179587</velocity>
          </limit>
        </axis>
      </joint>
      <joint name="joint_RMTarsus1" type="fixed">
        <parent>RMTibia</parent>
        <child>RMTarsus1</child>
        <pose>0.0 0.0 0.0 0.0 0.0 0.0</pose>
        <axis>
          <xyz>0.0 1.0 0.0</xyz>
          <limit>
            <lower>-3.1415841273552365</lower>
            <upper>3.1415841273552365</upper>
            <effort>10000000000.0</effort>
            <velocity>628.3185307179587</velocity>
          </limit>
        </axis>
      </joint>
      <joint name="joint_RMTarsus2" type="fixed">
        <parent>RMTarsus1</parent>
        <child>RMTarsus2</child>
        <pose>0.0 0.0 0.0 0.0 0.0 0.0</pose>
        <axis>
          <xyz>0.0 1.0 0.0</xyz>
          <limit>
            <lower>-3.141590306717268</lower>
            <upper>3.141590306717268</upper>
            <effort>10000000000.0</effort>
            <velocity>628.3185307179587</velocity>
          </limit>
        </axis>
      </joint>
      <joint name="joint_RMTarsus3" type="fixed">
        <parent>RMTarsus2</parent>
        <child>RMTarsus3</child>
        <pose>0.0 0.0 0.0 0.0 0.0 0.0</pose>
        <axis>
          <xyz>0.0 1.0 0.0</xyz>
          <limit>
            <lower>-3.1415813185581385</lower>
            <upper>3.1415813185581385</upper>
            <effort>10000000000.0</effort>
            <velocity>628.3185307179587</velocity>
          </limit>
        </axis>
      </joint>
      <joint name="joint_RMTarsus4" type="fixed">
        <parent>RMTarsus3</parent>
        <child>RMTarsus4</child>
        <pose>0.0 0.0 0.0 0.0 0.0 0.0</pose>
        <axis>
          <xyz>0.0 1.0 0.0</xyz>
          <limit>
            <lower>-3.14157869701418</lower>
            <upper>3.14157869701418</upper>
            <effort>10000000000.0</effort>
            <velocity>628.3185307179587</velocity>
          </limit>
        </axis>
      </joint>
      <joint name="joint_RMTarsus5" type="fixed">
        <parent>RMTarsus4</parent>
        <child>RMTarsus5</child>
        <pose>0.0 0.0 0.0 0.0 0.0 0.0</pose>
        <axis>
          <xyz>0.0 1.0 0.0</xyz>
          <limit>
            <lower>-3.1415740156856833</lower>
            <upper>3.1415740156856833</upper>
            <effort>10000000000.0</effort>
            <velocity>628.3185307179587</velocity>
          </limit>
        </axis>
      </joint>
      <joint name="joint_RMTibia" type="continuous">
        <parent>RMFemur_roll</parent>
        <child>RMTibia</child>
        <pose>0.0 0.0 0.0 0.0 0.0 0.0</pose>
        <axis>
          <xyz>0.0 1.0 0.0</xyz>
          <limit>
            <lower>1.5742404712255267</lower>
            <upper>2.4686521684717793</upper>
            <effort>10000000000.0</effort>
            <velocity>628.3185307179587</velocity>
          </limit>
        </axis>
      </joint>
      <joint name="joint_Rostrum" type="fixed">
        <parent>Head</parent>
        <child>Rostrum</child>
        <pose>0.0 0.0 0.0 0.0 0.0 0.0</pose>
        <axis>
          <xyz>0.0 1.0 0.0</xyz>
          <limit>
            <lower>-3.1415841273552365</lower>
            <upper>3.1415841273552365</upper>
            <effort>10000000000.0</effort>
            <velocity>628.3185307179587</velocity>
          </limit>
        </axis>
      </joint>
      <joint name="joint_RWing" type="fixed">
        <parent>RWing_yaw</parent>
        <child>RWing</child>
        <pose>0.0 0.0 0.0 0.0 0.0 0.0</pose>
        <axis>
          <xyz>0.0 1.0 0.0</xyz>
          <limit>
            <lower>-3.1434539534027595</lower>
            <upper>3.1434539534027595</upper>
            <effort>10000000000.0</effort>
            <velocity>628.3185307179587</velocity>
          </limit>
        </axis>
      </joint>
      <joint name="joint_RWing_roll" type="fixed">
        <parent>Thorax</parent>
        <child>RWing_roll</child>
        <pose>0.0 0.0 0.0 0.0 0.0 0.0</pose>
        <axis>
          <xyz>-0.0 -0.0 -1.0</xyz>
          <limit>
            <lower>-3.1415927410125732</lower>
            <upper>3.1415927410125732</upper>
            <effort>10000000000.0</effort>
            <velocity>628.3185307179587</velocity>
          </limit>
        </axis>
      </joint>
      <joint name="joint_RWing_yaw" type="fixed">
        <parent>RWing_roll</parent>
        <child>RWing_yaw</child>
        <pose>0.0 0.0 0.0 0.0 0.0 0.0</pose>
        <axis>
          <xyz>-1.0 -0.0 -0.0</xyz>
          <limit>
            <lower>-3.1415927410125732</lower>
            <upper>3.1415927410125732</upper>
            <effort>10000000000.0</effort>
            <velocity>628.3185307179587</velocity>
          </limit>
        </axis>
      </joint>
      <joint name="prismatic_support_1" type="fixed">
        <parent>world</parent>
        <child>prismatic_support_1</child>
        <pose>0.0 0.0 0.0 0.0 0.0 0.0</pose>
        <axis>
          <xyz>1.0 0.0 0.0</xyz>
          <limit>
            <lower>1.0</lower>
            <upper>-1.0</upper>
            <effort>0.0</effort>
            <velocity>100.0</velocity>
          </limit>
        </axis>
      </joint>
      <joint name="prismatic_support_2" type="fixed">
        <parent>prismatic_support_1</parent>
        <child>prismatic_support_2</child>
        <pose>0.0 0.0 0.0 0.0 0.0 0.0</pose>
        <axis>
          <xyz>0.0 0.0 1.0</xyz>
          <limit>
            <lower>1.0</lower>
            <upper>-1.0</upper>
            <effort>0.0</effort>
            <velocity>100.0</velocity>
          </limit>
        </axis>
      </joint>
      <joint name="revolute_support_1" type="fixed">
        <parent>prismatic_support_2</parent>
        <child>Thorax</child>
        <pose>0.0 0.0 0.0 0.0 0.0 0.0</pose>
        <axis>
          <xyz>0.0 1.0 0.0</xyz>
        </axis>
      </joint>
    </model>
  </world>
</sdf>
